Workbook
Name Klasser: OFFSET(Oppsett!$B$12,0,0,MAX(1,COUNTA(Oppsett!$B$12:$B$71)),1)
Name Moter: OFFSET(Oppsett!$C$12,0,0,MAX(1,COUNTA(Oppsett!$C$12:$C$31)),1)
Name Omrader: OFFSET(Oppsett!$F$12,0,0,MAX(1,COUNTA(Oppsett!$F$12:$F$35)),1)
Name Lysliste: 'Lister'!$A$2:$A$4
Name Statusar: 'Lister'!$B$2:$B$6
Name Malformer: 'Lister'!$D$2:$D$3
Name VelKlasse: 'Lister'!$F$2
Name ELEV_1ID: OFFSET('Elevar'!$A$2,0,0,MAX(1,COUNTA('Elevar'!$A$2:$A$41)),1)
Name ELEV_1HO: OFFSET('Elevar'!$B$2,0,0,MAX(1,COUNTA('Elevar'!$B$2:$B$41)),1)
Name ELEV_2AKV_FF: OFFSET('Elevar'!$C$2,0,0,MAX(1,COUNTA('Elevar'!$C$2:$C$41)),1)

Sheet Start her
B2: Trafikklys
B4: Kvar lærar melder inn det som ikkje er grønt. Møtet får eitt rutenett per klasse: elevane nedover, områda bortover, sterkaste lys i kvar rute.
B6: 1 Oppsett – skule, klassar, møtedatoar og kva område de set lys på.
B7: 2 Elevar – éi kolonne per klasse med namna. Då veit Innmelding kven som finst.
B8: 3 Innmelding – éi rad per ting du vil melde inn. Alt har nedtrekksliste.
B9: 4 Oversikt – i møtet. Vel møte og klasse øvst, så står rutenettet ferdig, med mest raudt øvst.
B10: 5 Elevkort – vel ein elev og sjå kva kvar lærar skreiv, og tiltaka som går.
B11: 6 Tiltak – det møtet blir samde om: kva, kven og til når.
B13: Alt skjer i denne fila. Ho treng ingen makroar, tillegg eller internett, så ho verkar også i eit lukka system som IOPsky.
B15: Kva lysa tyder
B16: Grønt – alt er i orden. Treng ikkje meldast inn, men du kan gjere det om du vil stadfeste at du har sett etter.
B17: Gult – noko å følgje med på. Kontaktlærar og faglærar handterer det i klassen, men møtet skal vite om det.
... B29: Klikk på filterpila i Møte-kolonnen når du vil sjå eitt møte om gongen. Rader du ikkje bruker, lèt du stå tomme.

Sheet Oppsett
B2: Oppsett
B4: Skule | C4: Hustadvika vidaregåande skole
B5: Skuleår | C5: 2026/2027
B6: Språk | C6: nynorsk | D6: bokmål / nynorsk
B7: Profilfarge | C7: #0093C9 | D7: ← fargen skulen sin profil bruker
B8: Logo (filnamn) | C8: profil/logo.png | D8: ← ligg i same mappe som denne fila
B11: Klassar | C11: Møte | D11: Dato | F11: Område | G11: Kva vi ser etter
B12: 1ID | C12: 1 · Haust | D12: 46282 | F12: Frammøte | G12: Fråvær, for sein komming, timar eleven ikkje er i
B13: 1HO | C13: 2 · Før jul | D13: 46352 | F13: Fagleg utvikling | G13: Måloppnåing, fare for IV, behov for tilrettelegging
B14: 2AKV/FF | F14: Arbeidsinnsats | G14: Innleveringar, innsats i timane, utstyr og bøker med
F15: Motivasjon | G15: Retning, meistringstru, om eleven vil vere her
F16: Trivsel | G16: Korleis eleven har det på skulen
F17: Klassemiljø | G17: Relasjonar, tilhøyrsle, utanforskap
F18: Heim og føresette | G18: Kontakt, samarbeid, informasjonsflyt
F19: Praktiske forhold | G19: Skyss, bustad, utstyr, økonomi
C33: ← eitt møte per rad, nyaste nedst

Sheet Elevar
A1: 1ID | B1: 1HO | C1: 2AKV/FF
A2: Amalie Røsberg | B2: Andrea Lyngstad | C2: Adrian Skotheim
A3: Brage Settem | B3: Emil Solheim | C3: Benedikte Haukås
A4: Eline Vevang | B4: Frida Oppheim | C4: Casper Rødset
A5: Håkon Tornes | B5: Isak Nerland | C5: Dina Fladset
A6: Ingrid Malmedal | B6: Julie Storli | C6: Elias Vorpenes
A7: Jonas Bergset | B7: Kristian Aandahl | C7: Hanna Bjørnerem
A8: Kaia Sylte | B8: Linnea Myrbø | C8: Iver Sandvik
A9: Leon Farstad | B9: Marius Hjelset | C9: Live Kjønnø
A10: Mathea Gjendem | B10: Nora Elvebakk | C10: Magnus Hasselø
A11: Noah Silseth | B11: Oliver Rakvåg | C11: Ronja Bugge
A12: Oda Hoem | B12: Selma Otterlei | C12: Simen Talberg
A13: Sander Vikan | B13: Tobias Kvalvåg | C13: Vilde Aarset

Sheet Innmelding
A1: Møte | B1: Klasse | C1: Elev | D1: Område | E1: Lys | F1: Merknad | G1: Lærar | H1: Lysverdi | I1: Elevkort
A2: 1 · Haust | B2: 1ID | C2: Brage Settem | D2: Frammøte | E2: Raudt | F2: 14 timar udokumentert fråvær på seks veker, mest måndag første time. | G2: K. Meringdal | H2: =IF(OR($E2="Raudt",$E2="Rødt",$E2="Raud",$E2="Rød"),3,IF($E2="Gult",2,IF(OR($E2="Grønt",$E2="Grøn",$E2="Grønn"),1,0))) | I2: =IF(AND($C2<>"",$A2='Oversikt'!$C$4,$B2='Oversikt'!$C$5,$C2='Elevkort'!$C$4),MAX(I$1:I1)+1,"")
A3: 1 · Haust | B3: 1ID | C3: Brage Settem | D3: Arbeidsinnsats | E3: Gult | F3: Har ikkje levert dei to siste innleveringane i norsk. | G3: M. Sæther | H3: =IF(OR($E3="Raudt",$E3="Rødt",$E3="Raud",$E3="Rød"),3,IF($E3="Gult",2,IF(OR($E3="Grønt",$E3="Grøn",$E3="Grønn"),1,0))) | I3: =IF(AND($C3<>"",$A3='Oversikt'!$C$4,$B3='Oversikt'!$C$5,$C3='Elevkort'!$C$4),MAX(I$1:I2)+1,"")
A4: 1 · Haust | B4: 1ID | C4: Brage Settem | D4: Motivasjon | E4: Gult | F4: Seier sjølv at han er usikker på om han har valt rett programområde. | G4: K. Meringdal | H4: =IF(OR($E4="Raudt",$E4="Rødt",$E4="Raud",$E4="Rød"),3,IF($E4="Gult",2,IF(OR($E4="Grønt",$E4="Grøn",$E4="Grønn"),1,0))) | I4: =IF(AND($C4<>"",$A4='Oversikt'!$C$4,$B4='Oversikt'!$C$5,$C4='Elevkort'!$C$4),MAX(I$1:I3)+1,"")
A5: 1 · Haust | B5: 1ID | C5: Eline Vevang | D5: Fagleg utvikling | E5: Gult | F5: Ligg an til låg måloppnåing i matematikk. Får ikkje tid nok på prøvene. | G5: T. Rødal | H5: =IF(OR($E5="Raudt",$E5="Rødt",$E5="Raud",$E5="Rød"),3,IF($E5="Gult",2,IF(OR($E5="Grønt",$E5="Grøn",$E5="Grønn"),1,0))) | I5: =IF(AND($C5<>"",$A5='Oversikt'!$C$4,$B5='Oversikt'!$C$5,$C5='Elevkort'!$C$4),MAX(I$1:I4)+1,"")
A6: 1 · Haust | B6: 1ID | C6: Eline Vevang | D6: Praktiske forhold | E6: Gult | F6: Lang skyss, kjem 10 minutt for seint tre dagar i veka. Bussen rekk ikkje. | G6: K. Meringdal | H6: =IF(OR($E6="Raudt",$E6="Rødt",$E6="Raud",$E6="Rød"),3,IF($E6="Gult",2,IF(OR($E6="Grønt",$E6="Grøn",$E6="Grønn"),1,0))) | I6: =IF(AND($C6<>"",$A6='Oversikt'!$C$4,$B6='Oversikt'!$C$5,$C6='Elevkort'!$C$4),MAX(I$1:I5)+1,"")
A7: 1 · Haust | B7: 1ID | C7: Kaia Sylte | D7: Trivsel | E7: Raudt | F7: Sit åleine i pausane. Har sagt til meg at ho gruar seg til skulen. | G7: K. Meringdal | H7: =IF(OR($E7="Raudt",$E7="Rødt",$E7="Raud",$E7="Rød"),3,IF($E7="Gult",2,IF(OR($E7="Grønt",$E7="Grøn",$E7="Grønn"),1,0))) | I7: =IF(AND($C7<>"",$A7='Oversikt'!$C$4,$B7='Oversikt'!$C$5,$C7='Elevkort'!$C$4),MAX(I$1:I6)+1,"")
A8: 1 · Haust | B8: 1ID | C8: Kaia Sylte | D8: Klassemiljø | E8: Gult | F8: Blir ikkje plukka når klassen deler seg i grupper. | G8: A. Hovde | H8: =IF(OR($E8="Raudt",$E8="Rødt",$E8="Raud",$E8="Rød"),3,IF($E8="Gult",2,IF(OR($E8="Grønt",$E8="Grøn",$E8="Grønn"),1,0))) | I8: =IF(AND($C8<>"",$A8='Oversikt'!$C$4,$B8='Oversikt'!$C$5,$C8='Elevkort'!$C$4),MAX(I$1:I7)+1,"")
A9: 1 · Haust | B9: 1ID | C9: Leon Farstad | D9: Arbeidsinnsats | E9: Gult | F9: Gløymer bøker og utstyr. Kjem ofte utan noko å skrive med. | G9: T. Rødal | H9: =IF(OR($E9="Raudt",$E9="Rødt",$E9="Raud",$E9="Rød"),3,IF($E9="Gult",2,IF(OR($E9="Grønt",$E9="Grøn",$E9="Grønn"),1,0))) | I9: =IF(AND($C9<>"",$A9='Oversikt'!$C$4,$B9='Oversikt'!$C$5,$C9='Elevkort'!$C$4),MAX(I$1:I8)+1,"")
A10: 1 · Haust | B10: 1ID | C10: Noah Silseth | D10: Fagleg utvikling | E10: Gult | F10: Slit med lesing av lange tekstar. Bør prøvast for tilrettelegging. | G10: M. Sæther | H10: =IF(OR($E10="Raudt",$E10="Rødt",$E10="Raud",$E10="Rød"),3,IF($E10="Gult",2,IF(OR($E10="Grønt",$E10="Grøn",$E10="Grønn"),1,0))) | I10: =IF(AND($C10<>"",$A10='Oversikt'!$C$4,$B10='Oversikt'!$C$5,$C10='Elevkort'!$C$4),MAX(I$1:I9)+1,"")
A11: 1 · Haust | B11: 1ID | C11: Sander Vikan | D11: Frammøte | E11: Gult | F11: Seks einskildtimar borte, alle etter lunsj. | G11: K. Meringdal | H11: =IF(OR($E11="Raudt",$E11="Rødt",$E11="Raud",$E11="Rød"),3,IF($E11="Gult",2,IF(OR($E11="Grønt",$E11="Grøn",$E11="Grønn"),1,0))) | I11: =IF(AND($C11<>"",$A11='Oversikt'!$C$4,$B11='Oversikt'!$C$5,$C11='Elevkort'!$C$4),MAX(I$1:I10)+1,"")
A12: 1 · Haust | B12: 1ID | C12: Amalie Røsberg | D12: Trivsel | E12: Grønt | F12: Har funne seg godt til rette. Nemner det berre så det er sett etter. | G12: K. Meringdal | H12: =IF(OR($E12="Raudt",$E12="Rødt",$E12="Raud",$E12="Rød"),3,IF($E12="Gult",2,IF(OR($E12="Grønt",$E12="Grøn",$E12="Grønn"),1,0))) | I12: =IF(AND($C12<>"",$A12='Oversikt'!$C$4,$B12='Oversikt'!$C$5,$C12='Elevkort'!$C$4),MAX(I$1:I11)+1,"")
A13: 1 · Haust | B13: 1HO | C13: Emil Solheim | D13: Frammøte | E13: Raudt | F13: Har vore borte heile veke 36 og 37 utan melding. | G13: S. Bakken | H13: =IF(OR($E13="Raudt",$E13="Rødt",$E13="Raud",$E13="Rød"),3,IF($E13="Gult",2,IF(OR($E13="Grønt",$E13="Grøn",$E13="Grønn"),1,0))) | I13: =IF(AND($C13<>"",$A13='Oversikt'!$C$4,$B13='Oversikt'!$C$5,$C13='Elevkort'!$C$4),MAX(I$1:I12)+1,"")
... A45: 2 · Før jul | B45: 2AKV/FF | C45: Ronja Bugge | D45: Motivasjon | E45: Grønt | F45: Har fått utplassering hos ein bedrift. Blir ut skuleåret. | G45: J. Vollan | H45: =IF(OR($E45="Raudt",$E45="Rødt",$E45="Raud",$E45="Rød"),3,IF($E45="Gult",2,IF(OR($E45="Grønt",$E45="Grøn",$E45="Grønn"),1,0))) | I45: =IF(AND($C45<>"",$A45='Oversikt'!$C$4,$B45='Oversikt'!$C$5,$C45='Elevkort'!$C$4),MAX(I$1:I44)+1,"")
H46: =IF(OR($E46="Raudt",$E46="Rødt",$E46="Raud",$E46="Rød"),3,IF($E46="Gult",2,IF(OR($E46="Grønt",$E46="Grøn",$E46="Grønn"),1,0))) | I46: =IF(AND($C46<>"",$A46='Oversikt'!$C$4,$B46='Oversikt'!$C$5,$C46='Elevkort'!$C$4),MAX(I$1:I45)+1,"")
H47: =IF(OR($E47="Raudt",$E47="Rødt",$E47="Raud",$E47="Rød"),3,IF($E47="Gult",2,IF(OR($E47="Grønt",$E47="Grøn",$E47="Grønn"),1,0))) | I47: =IF(AND($C47<>"",$A47='Oversikt'!$C$4,$B47='Oversikt'!$C$5,$C47='Elevkort'!$C$4),MAX(I$1:I46)+1,"")
H48: =IF(OR($E48="Raudt",$E48="Rødt",$E48="Raud",$E48="Rød"),3,IF($E48="Gult",2,IF(OR($E48="Grønt",$E48="Grøn",$E48="Grønn"),1,0))) | I48: =IF(AND($C48<>"",$A48='Oversikt'!$C$4,$B48='Oversikt'!$C$5,$C48='Elevkort'!$C$4),MAX(I$1:I47)+1,"")
H49: =IF(OR($E49="Raudt",$E49="Rødt",$E49="Raud",$E49="Rød"),3,IF($E49="Gult",2,IF(OR($E49="Grønt",$E49="Grøn",$E49="Grønn"),1,0))) | I49: =IF(AND($C49<>"",$A49='Oversikt'!$C$4,$B49='Oversikt'!$C$5,$C49='Elevkort'!$C$4),MAX(I$1:I48)+1,"")
H50: =IF(OR($E50="Raudt",$E50="Rødt",$E50="Raud",$E50="Rød"),3,IF($E50="Gult",2,IF(OR($E50="Grønt",$E50="Grøn",$E50="Grønn"),1,0))) | I50: =IF(AND($C50<>"",$A50='Oversikt'!$C$4,$B50='Oversikt'!$C$5,$C50='Elevkort'!$C$4),MAX(I$1:I49)+1,"")
H51: =IF(OR($E51="Raudt",$E51="Rødt",$E51="Raud",$E51="Rød"),3,IF($E51="Gult",2,IF(OR($E51="Grønt",$E51="Grøn",$E51="Grønn"),1,0))) | I51: =IF(AND($C51<>"",$A51='Oversikt'!$C$4,$B51='Oversikt'!$C$5,$C51='Elevkort'!$C$4),MAX(I$1:I50)+1,"")
H52: =IF(OR($E52="Raudt",$E52="Rødt",$E52="Raud",$E52="Rød"),3,IF($E52="Gult",2,IF(OR($E52="Grønt",$E52="Grøn",$E52="Grønn"),1,0))) | I52: =IF(AND($C52<>"",$A52='Oversikt'!$C$4,$B52='Oversikt'!$C$5,$C52='Elevkort'!$C$4),MAX(I$1:I51)+1,"")
H53: =IF(OR($E53="Raudt",$E53="Rødt",$E53="Raud",$E53="Rød"),3,IF($E53="Gult",2,IF(OR($E53="Grønt",$E53="Grøn",$E53="Grønn"),1,0))) | I53: =IF(AND($C53<>"",$A53='Oversikt'!$C$4,$B53='Oversikt'!$C$5,$C53='Elevkort'!$C$4),MAX(I$1:I52)+1,"")
H54: =IF(OR($E54="Raudt",$E54="Rødt",$E54="Raud",$E54="Rød"),3,IF($E54="Gult",2,IF(OR($E54="Grønt",$E54="Grøn",$E54="Grønn"),1,0))) | I54: =IF(AND($C54<>"",$A54='Oversikt'!$C$4,$B54='Oversikt'!$C$5,$C54='Elevkort'!$C$4),MAX(I$1:I53)+1,"")
H55: =IF(OR($E55="Raudt",$E55="Rødt",$E55="Raud",$E55="Rød"),3,IF($E55="Gult",2,IF(OR($E55="Grønt",$E55="Grøn",$E55="Grønn"),1,0))) | I55: =IF(AND($C55<>"",$A55='Oversikt'!$C$4,$B55='Oversikt'!$C$5,$C55='Elevkort'!$C$4),MAX(I$1:I54)+1,"")
H56: =IF(OR($E56="Raudt",$E56="Rødt",$E56="Raud",$E56="Rød"),3,IF($E56="Gult",2,IF(OR($E56="Grønt",$E56="Grøn",$E56="Grønn"),1,0))) | I56: =IF(AND($C56<>"",$A56='Oversikt'!$C$4,$B56='Oversikt'!$C$5,$C56='Elevkort'!$C$4),MAX(I$1:I55)+1,"")
H57: =IF(OR($E57="Raudt",$E57="Rødt",$E57="Raud",$E57="Rød"),3,IF($E57="Gult",2,IF(OR($E57="Grønt",$E57="Grøn",$E57="Grønn"),1,0))) | I57: =IF(AND($C57<>"",$A57='Oversikt'!$C$4,$B57='Oversikt'!$C$5,$C57='Elevkort'!$C$4),MAX(I$1:I56)+1,"")
... H701: =IF(OR($E701="Raudt",$E701="Rødt",$E701="Raud",$E701="Rød"),3,IF($E701="Gult",2,IF(OR($E701="Grønt",$E701="Grøn",$E701="Grønn"),1,0))) | I701: =IF(AND($C701<>"",$A701='Oversikt'!$C$4,$B701='Oversikt'!$C$5,$C701='Elevkort'!$C$4),MAX(I$1:I700)+1,"")

Sheet Tiltak
A1: Møte | B1: Klasse | C1: Elev | D1: Område | E1: Tiltak | F1: Ansvarleg | G1: Frist | H1: Status | I1: Elevkort
A2: 1 · Haust | B2: 1ID | C2: Brage Settem | D2: Frammøte | E2: Fast oppmøteavtale måndag morgon, kontaktlærar tek imot ved døra i fire veker. | F2: Kontaktlærar | G2: 46310 | H2: Avslutta | I2: =IF(AND($E2<>"",$B2='Oversikt'!$C$5,$C2='Elevkort'!$C$4),MAX(I$1:I1)+1,"")
A3: 1 · Haust | B3: 1ID | C3: Brage Settem | D3: Motivasjon | E3: Samtale med rådgivar om omval og om vegen mot læreplass. | F3: Rådgivar | G3: 46305 | H3: Avslutta | I3: =IF(AND($E3<>"",$B3='Oversikt'!$C$5,$C3='Elevkort'!$C$4),MAX(I$1:I2)+1,"")
A4: 1 · Haust | B4: 1ID | C4: Kaia Sylte | D4: Trivsel | E4: Kontakt med helsesjukepleiar. Kontaktlærar spør korleis det går kvar fredag. | F4: Kontaktlærar | G4: 46298 | H4: Blir følgd opp | I4: =IF(AND($E4<>"",$B4='Oversikt'!$C$5,$C4='Elevkort'!$C$4),MAX(I$1:I3)+1,"")
A5: 1 · Haust | B5: 1ID | C5: Eline Vevang | D5: Fagleg utvikling | E5: Utvida tid på prøver, og eit opplegg for rekning i studietida. | F5: Faglærar matematikk | G5: 46296 | H5: Avslutta | I5: =IF(AND($E5<>"",$B5='Oversikt'!$C$5,$C5='Elevkort'!$C$4),MAX(I$1:I4)+1,"")
A6: 1 · Haust | B6: 1ID | C6: Noah Silseth | D6: Fagleg utvikling | E6: Kartlegging av lesing, og lydbøker i norsk og samfunnsfag. | F6: Spesialpedagogisk team | G6: 46319 | H6: Avslutta | I6: =IF(AND($E6<>"",$B6='Oversikt'!$C$5,$C6='Elevkort'!$C$4),MAX(I$1:I5)+1,"")
A7: 1 · Haust | B7: 1HO | C7: Emil Solheim | D7: Frammøte | E7: Heimebesøk saman med rådgivar. Deretter ny plan for oppmøte. | F7: Rådgivar | G7: 46303 | H7: Vidareført | I7: =IF(AND($E7<>"",$B7='Oversikt'!$C$5,$C7='Elevkort'!$C$4),MAX(I$1:I6)+1,"")
A8: 1 · Haust | B8: 1HO | C8: Isak Nerland | D8: Arbeidsinnsats | E8: Telefonhotell i timane, og ei innlevering om gongen med kort frist. | F8: Faglærar | G8: 46312 | H8: Avslutta | I8: =IF(AND($E8<>"",$B8='Oversikt'!$C$5,$C8='Elevkort'!$C$4),MAX(I$1:I7)+1,"")
A9: 1 · Haust | B9: 1HO | C9: Selma Otterlei | D9: Praktiske forhold | E9: Søknad til utstyrsfondet for arbeidstøy. | F9: Kontaktlærar | G9: 46295 | H9: Avslutta | I9: =IF(AND($E9<>"",$B9='Oversikt'!$C$5,$C9='Elevkort'!$C$4),MAX(I$1:I8)+1,"")
A10: 1 · Haust | B10: 2AKV/FF | C10: Magnus Hasselø | D10: Fagleg utvikling | E10: Plan for å ta att manglande vurderingssituasjonar, ei per veke. | F10: Faglærar programfag | G10: 46346 | H10: Pågår | I10: =IF(AND($E10<>"",$B10='Oversikt'!$C$5,$C10='Elevkort'!$C$4),MAX(I$1:I9)+1,"")
A11: 2 · Før jul | B11: 1ID | C11: Mathea Gjendem | D11: Frammøte | E11: Samtale med eleven, deretter kontakt med føresette same veke. | F11: Kontaktlærar | G11: 46361 | H11: Ikkje starta | I11: =IF(AND($E11<>"",$B11='Oversikt'!$C$5,$C11='Elevkort'!$C$4),MAX(I$1:I10)+1,"")
A12: 2 · Før jul | B12: 1ID | C12: Kaia Sylte | D12: Trivsel | E12: Held fram med faste grupper i alle fag ut skuleåret. | F12: Alle faglærarar | G12: 46402 | H12: Pågår | I12: =IF(AND($E12<>"",$B12='Oversikt'!$C$5,$C12='Elevkort'!$C$4),MAX(I$1:I11)+1,"")
A13: 2 · Før jul | B13: 1HO | C13: Emil Solheim | D13: Frammøte | E13: Tverrfagleg møte med oppfølgingstenesta før jul. | F13: Rådgivar | G13: 46368 | H13: Ikkje starta | I13: =IF(AND($E13<>"",$B13='Oversikt'!$C$5,$C13='Elevkort'!$C$4),MAX(I$1:I12)+1,"")
... A15: 2 · Før jul | B15: 2AKV/FF | C15: Dina Fladset | D15: Trivsel | E15: Samtale om arbeidsmengd ved sida av skulen. Kontakt med helsesjukepleiar. | F15: Kontaktlærar | G15: 46366 | H15: Pågår | I15: =IF(AND($E15<>"",$B15='Oversikt'!$C$5,$C15='Elevkort'!$C$4),MAX(I$1:I14)+1,"")
I16: =IF(AND($E16<>"",$B16='Oversikt'!$C$5,$C16='Elevkort'!$C$4),MAX(I$1:I15)+1,"")
I17: =IF(AND($E17<>"",$B17='Oversikt'!$C$5,$C17='Elevkort'!$C$4),MAX(I$1:I16)+1,"")
I18: =IF(AND($E18<>"",$B18='Oversikt'!$C$5,$C18='Elevkort'!$C$4),MAX(I$1:I17)+1,"")
I19: =IF(AND($E19<>"",$B19='Oversikt'!$C$5,$C19='Elevkort'!$C$4),MAX(I$1:I18)+1,"")
I20: =IF(AND($E20<>"",$B20='Oversikt'!$C$5,$C20='Elevkort'!$C$4),MAX(I$1:I19)+1,"")
I21: =IF(AND($E21<>"",$B21='Oversikt'!$C$5,$C21='Elevkort'!$C$4),MAX(I$1:I20)+1,"")
I22: =IF(AND($E22<>"",$B22='Oversikt'!$C$5,$C22='Elevkort'!$C$4),MAX(I$1:I21)+1,"")
I23: =IF(AND($E23<>"",$B23='Oversikt'!$C$5,$C23='Elevkort'!$C$4),MAX(I$1:I22)+1,"")
I24: =IF(AND($E24<>"",$B24='Oversikt'!$C$5,$C24='Elevkort'!$C$4),MAX(I$1:I23)+1,"")
I25: =IF(AND($E25<>"",$B25='Oversikt'!$C$5,$C25='Elevkort'!$C$4),MAX(I$1:I24)+1,"")
I26: =IF(AND($E26<>"",$B26='Oversikt'!$C$5,$C26='Elevkort'!$C$4),MAX(I$1:I25)+1,"")
I27: =IF(AND($E27<>"",$B27='Oversikt'!$C$5,$C27='Elevkort'!$C$4),MAX(I$1:I26)+1,"")
... I251: =IF(AND($E251<>"",$B251='Oversikt'!$C$5,$C251='Elevkort'!$C$4),MAX(I$1:I250)+1,"")

Sheet Oversikt
B2: Elevstatus
B4: Møte | C4: 2 · Før jul | G4: =SUM(C9:C48) | H4: =SUM(D9:D48) | I4: =COUNTIF('Utrekning'!$E$2:$P$41,1) | J4: =COUNTIF('Utrekning'!$C$2:$C$41,">=1") | K4: =SUM(E9:E48)
B5: Klasse | C5: 1ID | G5: raude | H5: gule | I5: grøne | J5: elevar med noko meldt inn | K5: Opne tiltak
B6: Førre møte | C6: =IFERROR(IF(MATCH($C$4,'Oppsett'!$C$12:$C$31,0)>1,INDEX('Oppsett'!$C$12:$C$31,MATCH($C$4,'Oppsett'!$C$12:$C$31,0)-1)&"",""),"") | G6: Sortert med mest raudt øvst. Elevar utan noko meldt inn står grått nedst.
B7: ● grønt ▲ gult ■ raudt · 2 = to lærarar har meldt inn · ↑ verre enn førre møte ↓ betre ✱ ny sidan førre møte
B8: Elev | C8: ■ | D8: ▲ | E8: Tiltak | F8: ='Oppsett'!$F$12&"" | G8: ='Oppsett'!$F$13&"" | H8: ='Oppsett'!$F$14&"" | I8: ='Oppsett'!$F$15&"" | J8: ='Oppsett'!$F$16&"" | K8: ='Oppsett'!$F$17&"" | L8: ='Oppsett'!$F$18&"" | M8: ='Oppsett'!$F$19&"" | N8: ='Oppsett'!$F$20&"" | O8: ='Oppsett'!$F$21&"" | P8: ='Oppsett'!$F$22&"" | Q8: ='Oppsett'!$F$23&""
B9: =IFERROR(INDEX('Utrekning'!$B$2:$B$41,'Utrekning'!$D$2),"") | C9: =IF($B9="","",COUNTIF(INDEX('Utrekning'!$E$2:$P$41,'Utrekning'!$D$2,0),3)) | D9: =IF($B9="","",COUNTIF(INDEX('Utrekning'!$E$2:$P$41,'Utrekning'!$D$2,0),2)) | E9: =IF($B9="","",COUNTIFS('Tiltak'!$B$2:$B$251,$C$5,'Tiltak'!$C$2:$C$251,$B9,'Tiltak'!$E$2:$E$251,"<>",'Tiltak'!$H$2:$H$251,"<>Avslutta",'Tiltak'!$H$2:$H$251,"<>Avsluttet")) | F9: =IF(OR($B9="",INDEX('Utrekning'!$E$2:$E$41,'Utrekning'!$D$2)=0),"",CHOOSE(INDEX('Utrekning'!$E$2:$E$41,'Utrekning'!$D$2),"●","▲","■")&IF(INDEX('Utrekning'!$AC$2:$AC$41,'Utrekning'!$D$2)>1," "&INDEX('Utrekning'!$AC$2:$AC$41,'Utrekning'!$D$2),"")&IF($C$6="","",IF(INDEX('Utrekning'!$Q$2:$Q$41,'Utrekning'!$D$2)=0," ✱",IF(INDEX('Utrekning'!$E$2:$E$41,'Utrekning'!$D$2)>INDEX('Utrekning'!$Q$2:$Q$41,'Utrekning'!$D$2)," ↑",IF(INDEX('Utrekning'!$E$2:$E$41,'Utrekning'!$D$2)<INDEX('Utrekning'!$Q$2:$Q$41,'Utrekning'!$D$2)," ↓",""))))) | G9: =IF(OR($B9="",INDEX('Utrekning'!$F$2:$F$41,'Utrekning'!$D$2)=0),"",CHOOSE(INDEX('Utrekning'!$F$2:$F$41,'Utrekning'!$D$2),"●","▲","■")&IF(INDEX('Utrekning'!$AD$2:$AD$41,'Utrekning'!$D$2)>1," "&INDEX('Utrekning'!$AD$2:$AD$41,'Utrekning'!$D$2),"")&IF($C$6="","",IF(INDEX('Utrekning'!$R$2:$R$41,'Utrekning'!$D$2)=0," ✱",IF(INDEX('Utrekning'!$F$2:$F$41,'Utrekning'!$D$2)>INDEX('Utrekning'!$R$2:$R$41,'Utrekning'!$D$2)," ↑",IF(INDEX('Utrekning'!$F$2:$F$41,'Utrekning'!$D$2)<INDEX('Utrekning'!$R$2:$R$41,'Utrekning'!$D$2)," ↓",""))))) | H9: =IF(OR($B9="",INDEX('Utrekning'!$G$2:$G$41,'Utrekning'!$D$2)=0),"",CHOOSE(INDEX('Utrekning'!$G$2:$G$41,'Utrekning'!$D$2),"●","▲","■")&IF(INDEX('Utrekning'!$AE$2:$AE$41,'Utrekning'!$D$2)>1," "&INDEX('Utrekning'!$AE$2:$AE$41,'Utrekning'!$D$2),"")&IF($C$6="","",IF(INDEX('Utrekning'!$S$2:$S$41,'Utrekning'!$D$2)=0," ✱",IF(INDEX('Utrekning'!$G$2:$G$41,'Utrekning'!$D$2)>INDEX('Utrekning'!$S$2:$S$41,'Utrekning'!$D$2)," ↑",IF(INDEX('Utrekning'!$G$2:$G$41,'Utrekning'!$D$2)<INDEX('Utrekning'!$S$2:$S$41,'Utrekning'!$D$2)," ↓",""))))) | I9: =IF(OR($B9="",INDEX('Utrekning'!$H$2:$H$41,'Utrekning'!$D$2)=0),"",CHOOSE(INDEX('Utrekning'!$H$2:$H$41,'Utrekning'!$D$2),"●","▲","■")&IF(INDEX('Utrekning'!$AF$2:$AF$41,'Utrekning'!$D$2)>1," "&INDEX('Utrekning'!$AF$2:$AF$41,'Utrekning'!$D$2),"")&IF($C$6="","",IF(INDEX('Utrekning'!$T$2:$T$41,'Utrekning'!$D$2)=0," ✱",IF(INDEX('Utrekning'!$H$2:$H$41,'Utrekning'!$D$2)>INDEX('Utrekning'!$T$2:$T$41,'Utrekning'!$D$2)," ↑",IF(INDEX('Utrekning'!$H$2:$H$41,'Utrekning'!$D$2)<INDEX('Utrekning'!$T$2:$T$41,'Utrekning'!$D$2)," ↓",""))))) | J9: =IF(OR($B9="",INDEX('Utrekning'!$I$2:$I$41,'Utrekning'!$D$2)=0),"",CHOOSE(INDEX('Utrekning'!$I$2:$I$41,'Utrekning'!$D$2),"●","▲","■")&IF(INDEX('Utrekning'!$AG$2:$AG$41,'Utrekning'!$D$2)>1," "&INDEX('Utrekning'!$AG$2:$AG$41,'Utrekning'!$D$2),"")&IF($C$6="","",IF(INDEX('Utrekning'!$U$2:$U$41,'Utrekning'!$D$2)=0," ✱",IF(INDEX('Utrekning'!$I$2:$I$41,'Utrekning'!$D$2)>INDEX('Utrekning'!$U$2:$U$41,'Utrekning'!$D$2)," ↑",IF(INDEX('Utrekning'!$I$2:$I$41,'Utrekning'!$D$2)<INDEX('Utrekning'!$U$2:$U$41,'Utrekning'!$D$2)," ↓",""))))) | K9: =IF(OR($B9="",INDEX('Utrekning'!$J$2:$J$41,'Utrekning'!$D$2)=0),"",CHOOSE(INDEX('Utrekning'!$J$2:$J$41,'Utrekning'!$D$2),"●","▲","■")&IF(INDEX('Utrekning'!$AH$2:$AH$41,'Utrekning'!$D$2)>1," "&INDEX('Utrekning'!$AH$2:$AH$41,'Utrekning'!$D$2),"")&IF($C$6="","",IF(INDEX('Utrekning'!$V$2:$V$41,'Utrekning'!$D$2)=0," ✱",IF(INDEX('Utrekning'!$J$2:$J$41,'Utrekning'!$D$2)>INDEX('Utrekning'!$V$2:$V$41,'Utrekning'!$D$2)," ↑",IF(INDEX('Utrekning'!$J$2:$J$41,'Utrekning'!$D$2)<INDEX('Utrekning'!$V$2:$V$41,'Utrekning'!$D$2)," ↓",""))))) | L9: =IF(OR($B9="",INDEX('Utrekning'!$K$2:$K$41,'Utrekning'!$D$2)=0),"",CHOOSE(INDEX('Utrekning'!$K$2:$K$41,'Utrekning'!$D$2),"●","▲","■")&IF(INDEX('Utrekning'!$AI$2:$AI$41,'Utrekning'!$D$2)>1," "&INDEX('Utrekning'!$AI$2:$AI$41,'Utrekning'!$D$2),"")&IF($C$6="","",IF(INDEX('Utrekning'!$W$2:$W$41,'Utrekning'!$D$2)=0," ✱",IF(INDEX('Utrekning'!$K$2:$K$41,'Utrekning'!$D$2)>INDEX('Utrekning'!$W$2:$W$41,'Utrekning'!$D$2)," ↑",IF(INDEX('Utrekning'!$K$2:$K$41,'Utrekning'!$D$2)<INDEX('Utrekning'!$W$2:$W$41,'Utrekning'!$D$2)," ↓",""))))) | M9: =IF(OR($B9="",INDEX('Utrekning'!$L$2:$L$41,'Utrekning'!$D$2)=0),"",CHOOSE(INDEX('Utrekning'!$L$2:$L$41,'Utrekning'!$D$2),"●","▲","■")&IF(INDEX('Utrekning'!$AJ$2:$AJ$41,'Utrekning'!$D$2)>1," "&INDEX('Utrekning'!$AJ$2:$AJ$41,'Utrekning'!$D$2),"")&IF($C$6="","",IF(INDEX('Utrekning'!$X$2:$X$41,'Utrekning'!$D$2)=0," ✱",IF(INDEX('Utrekning'!$L$2:$L$41,'Utrekning'!$D$2)>INDEX('Utrekning'!$X$2:$X$41,'Utrekning'!$D$2)," ↑",IF(INDEX('Utrekning'!$L$2:$L$41,'Utrekning'!$D$2)<INDEX('Utrekning'!$X$2:$X$41,'Utrekning'!$D$2)," ↓",""))))) | N9: =IF(OR($B9="",INDEX('Utrekning'!$M$2:$M$41,'Utrekning'!$D$2)=0),"",CHOOSE(INDEX('Utrekning'!$M$2:$M$41,'Utrekning'!$D$2),"●","▲","■")&IF(INDEX('Utrekning'!$AK$2:$AK$41,'Utrekning'!$D$2)>1," "&INDEX('Utrekning'!$AK$2:$AK$41,'Utrekning'!$D$2),"")&IF($C$6="","",IF(INDEX('Utrekning'!$Y$2:$Y$41,'Utrekning'!$D$2)=0," ✱",IF(INDEX('Utrekning'!$M$2:$M$41,'Utrekning'!$D$2)>INDEX('Utrekning'!$Y$2:$Y$41,'Utrekning'!$D$2)," ↑",IF(INDEX('Utrekning'!$M$2:$M$41,'Utrekning'!$D$2)<INDEX('Utrekning'!$Y$2:$Y$41,'Utrekning'!$D$2)," ↓",""))))) | O9: =IF(OR($B9="",INDEX('Utrekning'!$N$2:$N$41,'Utrekning'!$D$2)=0),"",CHOOSE(INDEX('Utrekning'!$N$2:$N$41,'Utrekning'!$D$2),"●","▲","■")&IF(INDEX('Utrekning'!$AL$2:$AL$41,'Utrekning'!$D$2)>1," "&INDEX('Utrekning'!$AL$2:$AL$41,'Utrekning'!$D$2),"")&IF($C$6="","",IF(INDEX('Utrekning'!$Z$2:$Z$41,'Utrekning'!$D$2)=0," ✱",IF(INDEX('Utrekning'!$N$2:$N$41,'Utrekning'!$D$2)>INDEX('Utrekning'!$Z$2:$Z$41,'Utrekning'!$D$2)," ↑",IF(INDEX('Utrekning'!$N$2:$N$41,'Utrekning'!$D$2)<INDEX('Utrekning'!$Z$2:$Z$41,'Utrekning'!$D$2)," ↓",""))))) | P9: =IF(OR($B9="",INDEX('Utrekning'!$O$2:$O$41,'Utrekning'!$D$2)=0),"",CHOOSE(INDEX('Utrekning'!$O$2:$O$41,'Utrekning'!$D$2),"●","▲","■")&IF(INDEX('Utrekning'!$AM$2:$AM$41,'Utrekning'!$D$2)>1," "&INDEX('Utrekning'!$AM$2:$AM$41,'Utrekning'!$D$2),"")&IF($C$6="","",IF(INDEX('Utrekning'!$AA$2:$AA$41,'Utrekning'!$D$2)=0," ✱",IF(INDEX('Utrekning'!$O$2:$O$41,'Utrekning'!$D$2)>INDEX('Utrekning'!$AA$2:$AA$41,'Utrekning'!$D$2)," ↑",IF(INDEX('Utrekning'!$O$2:$O$41,'Utrekning'!$D$2)<INDEX('Utrekning'!$AA$2:$AA$41,'Utrekning'!$D$2)," ↓",""))))) | Q9: =IF(OR($B9="",INDEX('Utrekning'!$P$2:$P$41,'Utrekning'!$D$2)=0),"",CHOOSE(INDEX('Utrekning'!$P$2:$P$41,'Utrekning'!$D$2),"●","▲","■")&IF(INDEX('Utrekning'!$AN$2:$AN$41,'Utrekning'!$D$2)>1," "&INDEX('Utrekning'!$AN$2:$AN$41,'Utrekning'!$D$2),"")&IF($C$6="","",IF(INDEX('Utrekning'!$AB$2:$AB$41,'Utrekning'!$D$2)=0," ✱",IF(INDEX('Utrekning'!$P$2:$P$41,'Utrekning'!$D$2)>INDEX('Utrekning'!$AB$2:$AB$41,'Utrekning'!$D$2)," ↑",IF(INDEX('Utrekning'!$P$2:$P$41,'Utrekning'!$D$2)<INDEX('Utrekning'!$AB$2:$AB$41,'Utrekning'!$D$2)," ↓","")))))
B10: =IFERROR(INDEX('Utrekning'!$B$2:$B$41,'Utrekning'!$D$3),"") | C10: =IF($B10="","",COUNTIF(INDEX('Utrekning'!$E$2:$P$41,'Utrekning'!$D$3,0),3)) | D10: =IF($B10="","",COUNTIF(INDEX('Utrekning'!$E$2:$P$41,'Utrekning'!$D$3,0),2)) | E10: =IF($B10="","",COUNTIFS('Tiltak'!$B$2:$B$251,$C$5,'Tiltak'!$C$2:$C$251,$B10,'Tiltak'!$E$2:$E$251,"<>",'Tiltak'!$H$2:$H$251,"<>Avslutta",'Tiltak'!$H$2:$H$251,"<>Avsluttet")) | F10: =IF(OR($B10="",INDEX('Utrekning'!$E$2:$E$41,'Utrekning'!$D$3)=0),"",CHOOSE(INDEX('Utrekning'!$E$2:$E$41,'Utrekning'!$D$3),"●","▲","■")&IF(INDEX('Utrekning'!$AC$2:$AC$41,'Utrekning'!$D$3)>1," "&INDEX('Utrekning'!$AC$2:$AC$41,'Utrekning'!$D$3),"")&IF($C$6="","",IF(INDEX('Utrekning'!$Q$2:$Q$41,'Utrekning'!$D$3)=0," ✱",IF(INDEX('Utrekning'!$E$2:$E$41,'Utrekning'!$D$3)>INDEX('Utrekning'!$Q$2:$Q$41,'Utrekning'!$D$3)," ↑",IF(INDEX('Utrekning'!$E$2:$E$41,'Utrekning'!$D$3)<INDEX('Utrekning'!$Q$2:$Q$41,'Utrekning'!$D$3)," ↓",""))))) | G10: =IF(OR($B10="",INDEX('Utrekning'!$F$2:$F$41,'Utrekning'!$D$3)=0),"",CHOOSE(INDEX('Utrekning'!$F$2:$F$41,'Utrekning'!$D$3),"●","▲","■")&IF(INDEX('Utrekning'!$AD$2:$AD$41,'Utrekning'!$D$3)>1," "&INDEX('Utrekning'!$AD$2:$AD$41,'Utrekning'!$D$3),"")&IF($C$6="","",IF(INDEX('Utrekning'!$R$2:$R$41,'Utrekning'!$D$3)=0," ✱",IF(INDEX('Utrekning'!$F$2:$F$41,'Utrekning'!$D$3)>INDEX('Utrekning'!$R$2:$R$41,'Utrekning'!$D$3)," ↑",IF(INDEX('Utrekning'!$F$2:$F$41,'Utrekning'!$D$3)<INDEX('Utrekning'!$R$2:$R$41,'Utrekning'!$D$3)," ↓",""))))) | H10: =IF(OR($B10="",INDEX('Utrekning'!$G$2:$G$41,'Utrekning'!$D$3)=0),"",CHOOSE(INDEX('Utrekning'!$G$2:$G$41,'Utrekning'!$D$3),"●","▲","■")&IF(INDEX('Utrekning'!$AE$2:$AE$41,'Utrekning'!$D$3)>1," "&INDEX('Utrekning'!$AE$2:$AE$41,'Utrekning'!$D$3),"")&IF($C$6="","",IF(INDEX('Utrekning'!$S$2:$S$41,'Utrekning'!$D$3)=0," ✱",IF(INDEX('Utrekning'!$G$2:$G$41,'Utrekning'!$D$3)>INDEX('Utrekning'!$S$2:$S$41,'Utrekning'!$D$3)," ↑",IF(INDEX('Utrekning'!$G$2:$G$41,'Utrekning'!$D$3)<INDEX('Utrekning'!$S$2:$S$41,'Utrekning'!$D$3)," ↓",""))))) | I10: =IF(OR($B10="",INDEX('Utrekning'!$H$2:$H$41,'Utrekning'!$D$3)=0),"",CHOOSE(INDEX('Utrekning'!$H$2:$H$41,'Utrekning'!$D$3),"●","▲","■")&IF(INDEX('Utrekning'!$AF$2:$AF$41,'Utrekning'!$D$3)>1," "&INDEX('Utrekning'!$AF$2:$AF$41,'Utrekning'!$D$3),"")&IF($C$6="","",IF(INDEX('Utrekning'!$T$2:$T$41,'Utrekning'!$D$3)=0," ✱",IF(INDEX('Utrekning'!$H$2:$H$41,'Utrekning'!$D$3)>INDEX('Utrekning'!$T$2:$T$41,'Utrekning'!$D$3)," ↑",IF(INDEX('Utrekning'!$H$2:$H$41,'Utrekning'!$D$3)<INDEX('Utrekning'!$T$2:$T$41,'Utrekning'!$D$3)," ↓",""))))) | J10: =IF(OR($B10="",INDEX('Utrekning'!$I$2:$I$41,'Utrekning'!$D$3)=0),"",CHOOSE(INDEX('Utrekning'!$I$2:$I$41,'Utrekning'!$D$3),"●","▲","■")&IF(INDEX('Utrekning'!$AG$2:$AG$41,'Utrekning'!$D$3)>1," "&INDEX('Utrekning'!$AG$2:$AG$41,'Utrekning'!$D$3),"")&IF($C$6="","",IF(INDEX('Utrekning'!$U$2:$U$41,'Utrekning'!$D$3)=0," ✱",IF(INDEX('Utrekning'!$I$2:$I$41,'Utrekning'!$D$3)>INDEX('Utrekning'!$U$2:$U$41,'Utrekning'!$D$3)," ↑",IF(INDEX('Utrekning'!$I$2:$I$41,'Utrekning'!$D$3)<INDEX('Utrekning'!$U$2:$U$41,'Utrekning'!$D$3)," ↓",""))))) | K10: =IF(OR($B10="",INDEX('Utrekning'!$J$2:$J$41,'Utrekning'!$D$3)=0),"",CHOOSE(INDEX('Utrekning'!$J$2:$J$41,'Utrekning'!$D$3),"●","▲","■")&IF(INDEX('Utrekning'!$AH$2:$AH$41,'Utrekning'!$D$3)>1," "&INDEX('Utrekning'!$AH$2:$AH$41,'Utrekning'!$D$3),"")&IF($C$6="","",IF(INDEX('Utrekning'!$V$2:$V$41,'Utrekning'!$D$3)=0," ✱",IF(INDEX('Utrekning'!$J$2:$J$41,'Utrekning'!$D$3)>INDEX('Utrekning'!$V$2:$V$41,'Utrekning'!$D$3)," ↑",IF(INDEX('Utrekning'!$J$2:$J$41,'Utrekning'!$D$3)<INDEX('Utrekning'!$V$2:$V$41,'Utrekning'!$D$3)," ↓",""))))) | L10: =IF(OR($B10="",INDEX('Utrekning'!$K$2:$K$41,'Utrekning'!$D$3)=0),"",CHOOSE(INDEX('Utrekning'!$K$2:$K$41,'Utrekning'!$D$3),"●","▲","■")&IF(INDEX('Utrekning'!$AI$2:$AI$41,'Utrekning'!$D$3)>1," "&INDEX('Utrekning'!$AI$2:$AI$41,'Utrekning'!$D$3),"")&IF($C$6="","",IF(INDEX('Utrekning'!$W$2:$W$41,'Utrekning'!$D$3)=0," ✱",IF(INDEX('Utrekning'!$K$2:$K$41,'Utrekning'!$D$3)>INDEX('Utrekning'!$W$2:$W$41,'Utrekning'!$D$3)," ↑",IF(INDEX('Utrekning'!$K$2:$K$41,'Utrekning'!$D$3)<INDEX('Utrekning'!$W$2:$W$41,'Utrekning'!$D$3)," ↓",""))))) | M10: =IF(OR($B10="",INDEX('Utrekning'!$L$2:$L$41,'Utrekning'!$D$3)=0),"",CHOOSE(INDEX('Utrekning'!$L$2:$L$41,'Utrekning'!$D$3),"●","▲","■")&IF(INDEX('Utrekning'!$AJ$2:$AJ$41,'Utrekning'!$D$3)>1," "&INDEX('Utrekning'!$AJ$2:$AJ$41,'Utrekning'!$D$3),"")&IF($C$6="","",IF(INDEX('Utrekning'!$X$2:$X$41,'Utrekning'!$D$3)=0," ✱",IF(INDEX('Utrekning'!$L$2:$L$41,'Utrekning'!$D$3)>INDEX('Utrekning'!$X$2:$X$41,'Utrekning'!$D$3)," ↑",IF(INDEX('Utrekning'!$L$2:$L$41,'Utrekning'!$D$3)<INDEX('Utrekning'!$X$2:$X$41,'Utrekning'!$D$3)," ↓",""))))) | N10: =IF(OR($B10="",INDEX('Utrekning'!$M$2:$M$41,'Utrekning'!$D$3)=0),"",CHOOSE(INDEX('Utrekning'!$M$2:$M$41,'Utrekning'!$D$3),"●","▲","■")&IF(INDEX('Utrekning'!$AK$2:$AK$41,'Utrekning'!$D$3)>1," "&INDEX('Utrekning'!$AK$2:$AK$41,'Utrekning'!$D$3),"")&IF($C$6="","",IF(INDEX('Utrekning'!$Y$2:$Y$41,'Utrekning'!$D$3)=0," ✱",IF(INDEX('Utrekning'!$M$2:$M$41,'Utrekning'!$D$3)>INDEX('Utrekning'!$Y$2:$Y$41,'Utrekning'!$D$3)," ↑",IF(INDEX('Utrekning'!$M$2:$M$41,'Utrekning'!$D$3)<INDEX('Utrekning'!$Y$2:$Y$41,'Utrekning'!$D$3)," ↓",""))))) | O10: =IF(OR($B10="",INDEX('Utrekning'!$N$2:$N$41,'Utrekning'!$D$3)=0),"",CHOOSE(INDEX('Utrekning'!$N$2:$N$41,'Utrekning'!$D$3),"●","▲","■")&IF(INDEX('Utrekning'!$AL$2:$AL$41,'Utrekning'!$D$3)>1," "&INDEX('Utrekning'!$AL$2:$AL$41,'Utrekning'!$D$3),"")&IF($C$6="","",IF(INDEX('Utrekning'!$Z$2:$Z$41,'Utrekning'!$D$3)=0," ✱",IF(INDEX('Utrekning'!$N$2:$N$41,'Utrekning'!$D$3)>INDEX('Utrekning'!$Z$2:$Z$41,'Utrekning'!$D$3)," ↑",IF(INDEX('Utrekning'!$N$2:$N$41,'Utrekning'!$D$3)<INDEX('Utrekning'!$Z$2:$Z$41,'Utrekning'!$D$3)," ↓",""))))) | P10: =IF(OR($B10="",INDEX('Utrekning'!$O$2:$O$41,'Utrekning'!$D$3)=0),"",CHOOSE(INDEX('Utrekning'!$O$2:$O$41,'Utrekning'!$D$3),"●","▲","■")&IF(INDEX('Utrekning'!$AM$2:$AM$41,'Utrekning'!$D$3)>1," "&INDEX('Utrekning'!$AM$2:$AM$41,'Utrekning'!$D$3),"")&IF($C$6="","",IF(INDEX('Utrekning'!$AA$2:$AA$41,'Utrekning'!$D$3)=0," ✱",IF(INDEX('Utrekning'!$O$2:$O$41,'Utrekning'!$D$3)>INDEX('Utrekning'!$AA$2:$AA$41,'Utrekning'!$D$3)," ↑",IF(INDEX('Utrekning'!$O$2:$O$41,'Utrekning'!$D$3)<INDEX('Utrekning'!$AA$2:$AA$41,'Utrekning'!$D$3)," ↓",""))))) | Q10: =IF(OR($B10="",INDEX('Utrekning'!$P$2:$P$41,'Utrekning'!$D$3)=0),"",CHOOSE(INDEX('Utrekning'!$P$2:$P$41,'Utrekning'!$D$3),"●","▲","■")&IF(INDEX('Utrekning'!$AN$2:$AN$41,'Utrekning'!$D$3)>1," "&INDEX('Utrekning'!$AN$2:$AN$41,'Utrekning'!$D$3),"")&IF($C$6="","",IF(INDEX('Utrekning'!$AB$2:$AB$41,'Utrekning'!$D$3)=0," ✱",IF(INDEX('Utrekning'!$P$2:$P$41,'Utrekning'!$D$3)>INDEX('Utrekning'!$AB$2:$AB$41,'Utrekning'!$D$3)," ↑",IF(INDEX('Utrekning'!$P$2:$P$41,'Utrekning'!$D$3)<INDEX('Utrekning'!$AB$2:$AB$41,'Utrekning'!$D$3)," ↓","")))))
B11: =IFERROR(INDEX('Utrekning'!$B$2:$B$41,'Utrekning'!$D$4),"") | C11: =IF($B11="","",COUNTIF(INDEX('Utrekning'!$E$2:$P$41,'Utrekning'!$D$4,0),3)) | D11: =IF($B11="","",COUNTIF(INDEX('Utrekning'!$E$2:$P$41,'Utrekning'!$D$4,0),2)) | E11: =IF($B11="","",COUNTIFS('Tiltak'!$B$2:$B$251,$C$5,'Tiltak'!$C$2:$C$251,$B11,'Tiltak'!$E$2:$E$251,"<>",'Tiltak'!$H$2:$H$251,"<>Avslutta",'Tiltak'!$H$2:$H$251,"<>Avsluttet")) | F11: =IF(OR($B11="",INDEX('Utrekning'!$E$2:$E$41,'Utrekning'!$D$4)=0),"",CHOOSE(INDEX('Utrekning'!$E$2:$E$41,'Utrekning'!$D$4),"●","▲","■")&IF(INDEX('Utrekning'!$AC$2:$AC$41,'Utrekning'!$D$4)>1," "&INDEX('Utrekning'!$AC$2:$AC$41,'Utrekning'!$D$4),"")&IF($C$6="","",IF(INDEX('Utrekning'!$Q$2:$Q$41,'Utrekning'!$D$4)=0," ✱",IF(INDEX('Utrekning'!$E$2:$E$41,'Utrekning'!$D$4)>INDEX('Utrekning'!$Q$2:$Q$41,'Utrekning'!$D$4)," ↑",IF(INDEX('Utrekning'!$E$2:$E$41,'Utrekning'!$D$4)<INDEX('Utrekning'!$Q$2:$Q$41,'Utrekning'!$D$4)," ↓",""))))) | G11: =IF(OR($B11="",INDEX('Utrekning'!$F$2:$F$41,'Utrekning'!$D$4)=0),"",CHOOSE(INDEX('Utrekning'!$F$2:$F$41,'Utrekning'!$D$4),"●","▲","■")&IF(INDEX('Utrekning'!$AD$2:$AD$41,'Utrekning'!$D$4)>1," "&INDEX('Utrekning'!$AD$2:$AD$41,'Utrekning'!$D$4),"")&IF($C$6="","",IF(INDEX('Utrekning'!$R$2:$R$41,'Utrekning'!$D$4)=0," ✱",IF(INDEX('Utrekning'!$F$2:$F$41,'Utrekning'!$D$4)>INDEX('Utrekning'!$R$2:$R$41,'Utrekning'!$D$4)," ↑",IF(INDEX('Utrekning'!$F$2:$F$41,'Utrekning'!$D$4)<INDEX('Utrekning'!$R$2:$R$41,'Utrekning'!$D$4)," ↓",""))))) | H11: =IF(OR($B11="",INDEX('Utrekning'!$G$2:$G$41,'Utrekning'!$D$4)=0),"",CHOOSE(INDEX('Utrekning'!$G$2:$G$41,'Utrekning'!$D$4),"●","▲","■")&IF(INDEX('Utrekning'!$AE$2:$AE$41,'Utrekning'!$D$4)>1," "&INDEX('Utrekning'!$AE$2:$AE$41,'Utrekning'!$D$4),"")&IF($C$6="","",IF(INDEX('Utrekning'!$S$2:$S$41,'Utrekning'!$D$4)=0," ✱",IF(INDEX('Utrekning'!$G$2:$G$41,'Utrekning'!$D$4)>INDEX('Utrekning'!$S$2:$S$41,'Utrekning'!$D$4)," ↑",IF(INDEX('Utrekning'!$G$2:$G$41,'Utrekning'!$D$4)<INDEX('Utrekning'!$S$2:$S$41,'Utrekning'!$D$4)," ↓",""))))) | I11: =IF(OR($B11="",INDEX('Utrekning'!$H$2:$H$41,'Utrekning'!$D$4)=0),"",CHOOSE(INDEX('Utrekning'!$H$2:$H$41,'Utrekning'!$D$4),"●","▲","■")&IF(INDEX('Utrekning'!$AF$2:$AF$41,'Utrekning'!$D$4)>1," "&INDEX('Utrekning'!$AF$2:$AF$41,'Utrekning'!$D$4),"")&IF($C$6="","",IF(INDEX('Utrekning'!$T$2:$T$41,'Utrekning'!$D$4)=0," ✱",IF(INDEX('Utrekning'!$H$2:$H$41,'Utrekning'!$D$4)>INDEX('Utrekning'!$T$2:$T$41,'Utrekning'!$D$4)," ↑",IF(INDEX('Utrekning'!$H$2:$H$41,'Utrekning'!$D$4)<INDEX('Utrekning'!$T$2:$T$41,'Utrekning'!$D$4)," ↓",""))))) | J11: =IF(OR($B11="",INDEX('Utrekning'!$I$2:$I$41,'Utrekning'!$D$4)=0),"",CHOOSE(INDEX('Utrekning'!$I$2:$I$41,'Utrekning'!$D$4),"●","▲","■")&IF(INDEX('Utrekning'!$AG$2:$AG$41,'Utrekning'!$D$4)>1," "&INDEX('Utrekning'!$AG$2:$AG$41,'Utrekning'!$D$4),"")&IF($C$6="","",IF(INDEX('Utrekning'!$U$2:$U$41,'Utrekning'!$D$4)=0," ✱",IF(INDEX('Utrekning'!$I$2:$I$41,'Utrekning'!$D$4)>INDEX('Utrekning'!$U$2:$U$41,'Utrekning'!$D$4)," ↑",IF(INDEX('Utrekning'!$I$2:$I$41,'Utrekning'!$D$4)<INDEX('Utrekning'!$U$2:$U$41,'Utrekning'!$D$4)," ↓",""))))) | K11: =IF(OR($B11="",INDEX('Utrekning'!$J$2:$J$41,'Utrekning'!$D$4)=0),"",CHOOSE(INDEX('Utrekning'!$J$2:$J$41,'Utrekning'!$D$4),"●","▲","■")&IF(INDEX('Utrekning'!$AH$2:$AH$41,'Utrekning'!$D$4)>1," "&INDEX('Utrekning'!$AH$2:$AH$41,'Utrekning'!$D$4),"")&IF($C$6="","",IF(INDEX('Utrekning'!$V$2:$V$41,'Utrekning'!$D$4)=0," ✱",IF(INDEX('Utrekning'!$J$2:$J$41,'Utrekning'!$D$4)>INDEX('Utrekning'!$V$2:$V$41,'Utrekning'!$D$4)," ↑",IF(INDEX('Utrekning'!$J$2:$J$41,'Utrekning'!$D$4)<INDEX('Utrekning'!$V$2:$V$41,'Utrekning'!$D$4)," ↓",""))))) | L11: =IF(OR($B11="",INDEX('Utrekning'!$K$2:$K$41,'Utrekning'!$D$4)=0),"",CHOOSE(INDEX('Utrekning'!$K$2:$K$41,'Utrekning'!$D$4),"●","▲","■")&IF(INDEX('Utrekning'!$AI$2:$AI$41,'Utrekning'!$D$4)>1," "&INDEX('Utrekning'!$AI$2:$AI$41,'Utrekning'!$D$4),"")&IF($C$6="","",IF(INDEX('Utrekning'!$W$2:$W$41,'Utrekning'!$D$4)=0," ✱",IF(INDEX('Utrekning'!$K$2:$K$41,'Utrekning'!$D$4)>INDEX('Utrekning'!$W$2:$W$41,'Utrekning'!$D$4)," ↑",IF(INDEX('Utrekning'!$K$2:$K$41,'Utrekning'!$D$4)<INDEX('Utrekning'!$W$2:$W$41,'Utrekning'!$D$4)," ↓",""))))) | M11: =IF(OR($B11="",INDEX('Utrekning'!$L$2:$L$41,'Utrekning'!$D$4)=0),"",CHOOSE(INDEX('Utrekning'!$L$2:$L$41,'Utrekning'!$D$4),"●","▲","■")&IF(INDEX('Utrekning'!$AJ$2:$AJ$41,'Utrekning'!$D$4)>1," "&INDEX('Utrekning'!$AJ$2:$AJ$41,'Utrekning'!$D$4),"")&IF($C$6="","",IF(INDEX('Utrekning'!$X$2:$X$41,'Utrekning'!$D$4)=0," ✱",IF(INDEX('Utrekning'!$L$2:$L$41,'Utrekning'!$D$4)>INDEX('Utrekning'!$X$2:$X$41,'Utrekning'!$D$4)," ↑",IF(INDEX('Utrekning'!$L$2:$L$41,'Utrekning'!$D$4)<INDEX('Utrekning'!$X$2:$X$41,'Utrekning'!$D$4)," ↓",""))))) | N11: =IF(OR($B11="",INDEX('Utrekning'!$M$2:$M$41,'Utrekning'!$D$4)=0),"",CHOOSE(INDEX('Utrekning'!$M$2:$M$41,'Utrekning'!$D$4),"●","▲","■")&IF(INDEX('Utrekning'!$AK$2:$AK$41,'Utrekning'!$D$4)>1," "&INDEX('Utrekning'!$AK$2:$AK$41,'Utrekning'!$D$4),"")&IF($C$6="","",IF(INDEX('Utrekning'!$Y$2:$Y$41,'Utrekning'!$D$4)=0," ✱",IF(INDEX('Utrekning'!$M$2:$M$41,'Utrekning'!$D$4)>INDEX('Utrekning'!$Y$2:$Y$41,'Utrekning'!$D$4)," ↑",IF(INDEX('Utrekning'!$M$2:$M$41,'Utrekning'!$D$4)<INDEX('Utrekning'!$Y$2:$Y$41,'Utrekning'!$D$4)," ↓",""))))) | O11: =IF(OR($B11="",INDEX('Utrekning'!$N$2:$N$41,'Utrekning'!$D$4)=0),"",CHOOSE(INDEX('Utrekning'!$N$2:$N$41,'Utrekning'!$D$4),"●","▲","■")&IF(INDEX('Utrekning'!$AL$2:$AL$41,'Utrekning'!$D$4)>1," "&INDEX('Utrekning'!$AL$2:$AL$41,'Utrekning'!$D$4),"")&IF($C$6="","",IF(INDEX('Utrekning'!$Z$2:$Z$41,'Utrekning'!$D$4)=0," ✱",IF(INDEX('Utrekning'!$N$2:$N$41,'Utrekning'!$D$4)>INDEX('Utrekning'!$Z$2:$Z$41,'Utrekning'!$D$4)," ↑",IF(INDEX('Utrekning'!$N$2:$N$41,'Utrekning'!$D$4)<INDEX('Utrekning'!$Z$2:$Z$41,'Utrekning'!$D$4)," ↓",""))))) | P11: =IF(OR($B11="",INDEX('Utrekning'!$O$2:$O$41,'Utrekning'!$D$4)=0),"",CHOOSE(INDEX('Utrekning'!$O$2:$O$41,'Utrekning'!$D$4),"●","▲","■")&IF(INDEX('Utrekning'!$AM$2:$AM$41,'Utrekning'!$D$4)>1," "&INDEX('Utrekning'!$AM$2:$AM$41,'Utrekning'!$D$4),"")&IF($C$6="","",IF(INDEX('Utrekning'!$AA$2:$AA$41,'Utrekning'!$D$4)=0," ✱",IF(INDEX('Utrekning'!$O$2:$O$41,'Utrekning'!$D$4)>INDEX('Utrekning'!$AA$2:$AA$41,'Utrekning'!$D$4)," ↑",IF(INDEX('Utrekning'!$O$2:$O$41,'Utrekning'!$D$4)<INDEX('Utrekning'!$AA$2:$AA$41,'Utrekning'!$D$4)," ↓",""))))) | Q11: =IF(OR($B11="",INDEX('Utrekning'!$P$2:$P$41,'Utrekning'!$D$4)=0),"",CHOOSE(INDEX('Utrekning'!$P$2:$P$41,'Utrekning'!$D$4),"●","▲","■")&IF(INDEX('Utrekning'!$AN$2:$AN$41,'Utrekning'!$D$4)>1," "&INDEX('Utrekning'!$AN$2:$AN$41,'Utrekning'!$D$4),"")&IF($C$6="","",IF(INDEX('Utrekning'!$AB$2:$AB$41,'Utrekning'!$D$4)=0," ✱",IF(INDEX('Utrekning'!$P$2:$P$41,'Utrekning'!$D$4)>INDEX('Utrekning'!$AB$2:$AB$41,'Utrekning'!$D$4)," ↑",IF(INDEX('Utrekning'!$P$2:$P$41,'Utrekning'!$D$4)<INDEX('Utrekning'!$AB$2:$AB$41,'Utrekning'!$D$4)," ↓","")))))
B12: =IFERROR(INDEX('Utrekning'!$B$2:$B$41,'Utrekning'!$D$5),"") | C12: =IF($B12="","",COUNTIF(INDEX('Utrekning'!$E$2:$P$41,'Utrekning'!$D$5,0),3)) | D12: =IF($B12="","",COUNTIF(INDEX('Utrekning'!$E$2:$P$41,'Utrekning'!$D$5,0),2)) | E12: =IF($B12="","",COUNTIFS('Tiltak'!$B$2:$B$251,$C$5,'Tiltak'!$C$2:$C$251,$B12,'Tiltak'!$E$2:$E$251,"<>",'Tiltak'!$H$2:$H$251,"<>Avslutta",'Tiltak'!$H$2:$H$251,"<>Avsluttet")) | F12: =IF(OR($B12="",INDEX('Utrekning'!$E$2:$E$41,'Utrekning'!$D$5)=0),"",CHOOSE(INDEX('Utrekning'!$E$2:$E$41,'Utrekning'!$D$5),"●","▲","■")&IF(INDEX('Utrekning'!$AC$2:$AC$41,'Utrekning'!$D$5)>1," "&INDEX('Utrekning'!$AC$2:$AC$41,'Utrekning'!$D$5),"")&IF($C$6="","",IF(INDEX('Utrekning'!$Q$2:$Q$41,'Utrekning'!$D$5)=0," ✱",IF(INDEX('Utrekning'!$E$2:$E$41,'Utrekning'!$D$5)>INDEX('Utrekning'!$Q$2:$Q$41,'Utrekning'!$D$5)," ↑",IF(INDEX('Utrekning'!$E$2:$E$41,'Utrekning'!$D$5)<INDEX('Utrekning'!$Q$2:$Q$41,'Utrekning'!$D$5)," ↓",""))))) | G12: =IF(OR($B12="",INDEX('Utrekning'!$F$2:$F$41,'Utrekning'!$D$5)=0),"",CHOOSE(INDEX('Utrekning'!$F$2:$F$41,'Utrekning'!$D$5),"●","▲","■")&IF(INDEX('Utrekning'!$AD$2:$AD$41,'Utrekning'!$D$5)>1," "&INDEX('Utrekning'!$AD$2:$AD$41,'Utrekning'!$D$5),"")&IF($C$6="","",IF(INDEX('Utrekning'!$R$2:$R$41,'Utrekning'!$D$5)=0," ✱",IF(INDEX('Utrekning'!$F$2:$F$41,'Utrekning'!$D$5)>INDEX('Utrekning'!$R$2:$R$41,'Utrekning'!$D$5)," ↑",IF(INDEX('Utrekning'!$F$2:$F$41,'Utrekning'!$D$5)<INDEX('Utrekning'!$R$2:$R$41,'Utrekning'!$D$5)," ↓",""))))) | H12: =IF(OR($B12="",INDEX('Utrekning'!$G$2:$G$41,'Utrekning'!$D$5)=0),"",CHOOSE(INDEX('Utrekning'!$G$2:$G$41,'Utrekning'!$D$5),"●","▲","■")&IF(INDEX('Utrekning'!$AE$2:$AE$41,'Utrekning'!$D$5)>1," "&INDEX('Utrekning'!$AE$2:$AE$41,'Utrekning'!$D$5),"")&IF($C$6="","",IF(INDEX('Utrekning'!$S$2:$S$41,'Utrekning'!$D$5)=0," ✱",IF(INDEX('Utrekning'!$G$2:$G$41,'Utrekning'!$D$5)>INDEX('Utrekning'!$S$2:$S$41,'Utrekning'!$D$5)," ↑",IF(INDEX('Utrekning'!$G$2:$G$41,'Utrekning'!$D$5)<INDEX('Utrekning'!$S$2:$S$41,'Utrekning'!$D$5)," ↓",""))))) | I12: =IF(OR($B12="",INDEX('Utrekning'!$H$2:$H$41,'Utrekning'!$D$5)=0),"",CHOOSE(INDEX('Utrekning'!$H$2:$H$41,'Utrekning'!$D$5),"●","▲","■")&IF(INDEX('Utrekning'!$AF$2:$AF$41,'Utrekning'!$D$5)>1," "&INDEX('Utrekning'!$AF$2:$AF$41,'Utrekning'!$D$5),"")&IF($C$6="","",IF(INDEX('Utrekning'!$T$2:$T$41,'Utrekning'!$D$5)=0," ✱",IF(INDEX('Utrekning'!$H$2:$H$41,'Utrekning'!$D$5)>INDEX('Utrekning'!$T$2:$T$41,'Utrekning'!$D$5)," ↑",IF(INDEX('Utrekning'!$H$2:$H$41,'Utrekning'!$D$5)<INDEX('Utrekning'!$T$2:$T$41,'Utrekning'!$D$5)," ↓",""))))) | J12: =IF(OR($B12="",INDEX('Utrekning'!$I$2:$I$41,'Utrekning'!$D$5)=0),"",CHOOSE(INDEX('Utrekning'!$I$2:$I$41,'Utrekning'!$D$5),"●","▲","■")&IF(INDEX('Utrekning'!$AG$2:$AG$41,'Utrekning'!$D$5)>1," "&INDEX('Utrekning'!$AG$2:$AG$41,'Utrekning'!$D$5),"")&IF($C$6="","",IF(INDEX('Utrekning'!$U$2:$U$41,'Utrekning'!$D$5)=0," ✱",IF(INDEX('Utrekning'!$I$2:$I$41,'Utrekning'!$D$5)>INDEX('Utrekning'!$U$2:$U$41,'Utrekning'!$D$5)," ↑",IF(INDEX('Utrekning'!$I$2:$I$41,'Utrekning'!$D$5)<INDEX('Utrekning'!$U$2:$U$41,'Utrekning'!$D$5)," ↓",""))))) | K12: =IF(OR($B12="",INDEX('Utrekning'!$J$2:$J$41,'Utrekning'!$D$5)=0),"",CHOOSE(INDEX('Utrekning'!$J$2:$J$41,'Utrekning'!$D$5),"●","▲","■")&IF(INDEX('Utrekning'!$AH$2:$AH$41,'Utrekning'!$D$5)>1," "&INDEX('Utrekning'!$AH$2:$AH$41,'Utrekning'!$D$5),"")&IF($C$6="","",IF(INDEX('Utrekning'!$V$2:$V$41,'Utrekning'!$D$5)=0," ✱",IF(INDEX('Utrekning'!$J$2:$J$41,'Utrekning'!$D$5)>INDEX('Utrekning'!$V$2:$V$41,'Utrekning'!$D$5)," ↑",IF(INDEX('Utrekning'!$J$2:$J$41,'Utrekning'!$D$5)<INDEX('Utrekning'!$V$2:$V$41,'Utrekning'!$D$5)," ↓",""))))) | L12: =IF(OR($B12="",INDEX('Utrekning'!$K$2:$K$41,'Utrekning'!$D$5)=0),"",CHOOSE(INDEX('Utrekning'!$K$2:$K$41,'Utrekning'!$D$5),"●","▲","■")&IF(INDEX('Utrekning'!$AI$2:$AI$41,'Utrekning'!$D$5)>1," "&INDEX('Utrekning'!$AI$2:$AI$41,'Utrekning'!$D$5),"")&IF($C$6="","",IF(INDEX('Utrekning'!$W$2:$W$41,'Utrekning'!$D$5)=0," ✱",IF(INDEX('Utrekning'!$K$2:$K$41,'Utrekning'!$D$5)>INDEX('Utrekning'!$W$2:$W$41,'Utrekning'!$D$5)," ↑",IF(INDEX('Utrekning'!$K$2:$K$41,'Utrekning'!$D$5)<INDEX('Utrekning'!$W$2:$W$41,'Utrekning'!$D$5)," ↓",""))))) | M12: =IF(OR($B12="",INDEX('Utrekning'!$L$2:$L$41,'Utrekning'!$D$5)=0),"",CHOOSE(INDEX('Utrekning'!$L$2:$L$41,'Utrekning'!$D$5),"●","▲","■")&IF(INDEX('Utrekning'!$AJ$2:$AJ$41,'Utrekning'!$D$5)>1," "&INDEX('Utrekning'!$AJ$2:$AJ$41,'Utrekning'!$D$5),"")&IF($C$6="","",IF(INDEX('Utrekning'!$X$2:$X$41,'Utrekning'!$D$5)=0," ✱",IF(INDEX('Utrekning'!$L$2:$L$41,'Utrekning'!$D$5)>INDEX('Utrekning'!$X$2:$X$41,'Utrekning'!$D$5)," ↑",IF(INDEX('Utrekning'!$L$2:$L$41,'Utrekning'!$D$5)<INDEX('Utrekning'!$X$2:$X$41,'Utrekning'!$D$5)," ↓",""))))) | N12: =IF(OR($B12="",INDEX('Utrekning'!$M$2:$M$41,'Utrekning'!$D$5)=0),"",CHOOSE(INDEX('Utrekning'!$M$2:$M$41,'Utrekning'!$D$5),"●","▲","■")&IF(INDEX('Utrekning'!$AK$2:$AK$41,'Utrekning'!$D$5)>1," "&INDEX('Utrekning'!$AK$2:$AK$41,'Utrekning'!$D$5),"")&IF($C$6="","",IF(INDEX('Utrekning'!$Y$2:$Y$41,'Utrekning'!$D$5)=0," ✱",IF(INDEX('Utrekning'!$M$2:$M$41,'Utrekning'!$D$5)>INDEX('Utrekning'!$Y$2:$Y$41,'Utrekning'!$D$5)," ↑",IF(INDEX('Utrekning'!$M$2:$M$41,'Utrekning'!$D$5)<INDEX('Utrekning'!$Y$2:$Y$41,'Utrekning'!$D$5)," ↓",""))))) | O12: =IF(OR($B12="",INDEX('Utrekning'!$N$2:$N$41,'Utrekning'!$D$5)=0),"",CHOOSE(INDEX('Utrekning'!$N$2:$N$41,'Utrekning'!$D$5),"●","▲","■")&IF(INDEX('Utrekning'!$AL$2:$AL$41,'Utrekning'!$D$5)>1," "&INDEX('Utrekning'!$AL$2:$AL$41,'Utrekning'!$D$5),"")&IF($C$6="","",IF(INDEX('Utrekning'!$Z$2:$Z$41,'Utrekning'!$D$5)=0," ✱",IF(INDEX('Utrekning'!$N$2:$N$41,'Utrekning'!$D$5)>INDEX('Utrekning'!$Z$2:$Z$41,'Utrekning'!$D$5)," ↑",IF(INDEX('Utrekning'!$N$2:$N$41,'Utrekning'!$D$5)<INDEX('Utrekning'!$Z$2:$Z$41,'Utrekning'!$D$5)," ↓",""))))) | P12: =IF(OR($B12="",INDEX('Utrekning'!$O$2:$O$41,'Utrekning'!$D$5)=0),"",CHOOSE(INDEX('Utrekning'!$O$2:$O$41,'Utrekning'!$D$5),"●","▲","■")&IF(INDEX('Utrekning'!$AM$2:$AM$41,'Utrekning'!$D$5)>1," "&INDEX('Utrekning'!$AM$2:$AM$41,'Utrekning'!$D$5),"")&IF($C$6="","",IF(INDEX('Utrekning'!$AA$2:$AA$41,'Utrekning'!$D$5)=0," ✱",IF(INDEX('Utrekning'!$O$2:$O$41,'Utrekning'!$D$5)>INDEX('Utrekning'!$AA$2:$AA$41,'Utrekning'!$D$5)," ↑",IF(INDEX('Utrekning'!$O$2:$O$41,'Utrekning'!$D$5)<INDEX('Utrekning'!$AA$2:$AA$41,'Utrekning'!$D$5)," ↓",""))))) | Q12: =IF(OR($B12="",INDEX('Utrekning'!$P$2:$P$41,'Utrekning'!$D$5)=0),"",CHOOSE(INDEX('Utrekning'!$P$2:$P$41,'Utrekning'!$D$5),"●","▲","■")&IF(INDEX('Utrekning'!$AN$2:$AN$41,'Utrekning'!$D$5)>1," "&INDEX('Utrekning'!$AN$2:$AN$41,'Utrekning'!$D$5),"")&IF($C$6="","",IF(INDEX('Utrekning'!$AB$2:$AB$41,'Utrekning'!$D$5)=0," ✱",IF(INDEX('Utrekning'!$P$2:$P$41,'Utrekning'!$D$5)>INDEX('Utrekning'!$AB$2:$AB$41,'Utrekning'!$D$5)," ↑",IF(INDEX('Utrekning'!$P$2:$P$41,'Utrekning'!$D$5)<INDEX('Utrekning'!$AB$2:$AB$41,'Utrekning'!$D$5)," ↓","")))))
B13: =IFERROR(INDEX('Utrekning'!$B$2:$B$41,'Utrekning'!$D$6),"") | C13: =IF($B13="","",COUNTIF(INDEX('Utrekning'!$E$2:$P$41,'Utrekning'!$D$6,0),3)) | D13: =IF($B13="","",COUNTIF(INDEX('Utrekning'!$E$2:$P$41,'Utrekning'!$D$6,0),2)) | E13: =IF($B13="","",COUNTIFS('Tiltak'!$B$2:$B$251,$C$5,'Tiltak'!$C$2:$C$251,$B13,'Tiltak'!$E$2:$E$251,"<>",'Tiltak'!$H$2:$H$251,"<>Avslutta",'Tiltak'!$H$2:$H$251,"<>Avsluttet")) | F13: =IF(OR($B13="",INDEX('Utrekning'!$E$2:$E$41,'Utrekning'!$D$6)=0),"",CHOOSE(INDEX('Utrekning'!$E$2:$E$41,'Utrekning'!$D$6),"●","▲","■")&IF(INDEX('Utrekning'!$AC$2:$AC$41,'Utrekning'!$D$6)>1," "&INDEX('Utrekning'!$AC$2:$AC$41,'Utrekning'!$D$6),"")&IF($C$6="","",IF(INDEX('Utrekning'!$Q$2:$Q$41,'Utrekning'!$D$6)=0," ✱",IF(INDEX('Utrekning'!$E$2:$E$41,'Utrekning'!$D$6)>INDEX('Utrekning'!$Q$2:$Q$41,'Utrekning'!$D$6)," ↑",IF(INDEX('Utrekning'!$E$2:$E$41,'Utrekning'!$D$6)<INDEX('Utrekning'!$Q$2:$Q$41,'Utrekning'!$D$6)," ↓",""))))) | G13: =IF(OR($B13="",INDEX('Utrekning'!$F$2:$F$41,'Utrekning'!$D$6)=0),"",CHOOSE(INDEX('Utrekning'!$F$2:$F$41,'Utrekning'!$D$6),"●","▲","■")&IF(INDEX('Utrekning'!$AD$2:$AD$41,'Utrekning'!$D$6)>1," "&INDEX('Utrekning'!$AD$2:$AD$41,'Utrekning'!$D$6),"")&IF($C$6="","",IF(INDEX('Utrekning'!$R$2:$R$41,'Utrekning'!$D$6)=0," ✱",IF(INDEX('Utrekning'!$F$2:$F$41,'Utrekning'!$D$6)>INDEX('Utrekning'!$R$2:$R$41,'Utrekning'!$D$6)," ↑",IF(INDEX('Utrekning'!$F$2:$F$41,'Utrekning'!$D$6)<INDEX('Utrekning'!$R$2:$R$41,'Utrekning'!$D$6)," ↓",""))))) | H13: =IF(OR($B13="",INDEX('Utrekning'!$G$2:$G$41,'Utrekning'!$D$6)=0),"",CHOOSE(INDEX('Utrekning'!$G$2:$G$41,'Utrekning'!$D$6),"●","▲","■")&IF(INDEX('Utrekning'!$AE$2:$AE$41,'Utrekning'!$D$6)>1," "&INDEX('Utrekning'!$AE$2:$AE$41,'Utrekning'!$D$6),"")&IF($C$6="","",IF(INDEX('Utrekning'!$S$2:$S$41,'Utrekning'!$D$6)=0," ✱",IF(INDEX('Utrekning'!$G$2:$G$41,'Utrekning'!$D$6)>INDEX('Utrekning'!$S$2:$S$41,'Utrekning'!$D$6)," ↑",IF(INDEX('Utrekning'!$G$2:$G$41,'Utrekning'!$D$6)<INDEX('Utrekning'!$S$2:$S$41,'Utrekning'!$D$6)," ↓",""))))) | I13: =IF(OR($B13="",INDEX('Utrekning'!$H$2:$H$41,'Utrekning'!$D$6)=0),"",CHOOSE(INDEX('Utrekning'!$H$2:$H$41,'Utrekning'!$D$6),"●","▲","■")&IF(INDEX('Utrekning'!$AF$2:$AF$41,'Utrekning'!$D$6)>1," "&INDEX('Utrekning'!$AF$2:$AF$41,'Utrekning'!$D$6),"")&IF($C$6="","",IF(INDEX('Utrekning'!$T$2:$T$41,'Utrekning'!$D$6)=0," ✱",IF(INDEX('Utrekning'!$H$2:$H$41,'Utrekning'!$D$6)>INDEX('Utrekning'!$T$2:$T$41,'Utrekning'!$D$6)," ↑",IF(INDEX('Utrekning'!$H$2:$H$41,'Utrekning'!$D$6)<INDEX('Utrekning'!$T$2:$T$41,'Utrekning'!$D$6)," ↓",""))))) | J13: =IF(OR($B13="",INDEX('Utrekning'!$I$2:$I$41,'Utrekning'!$D$6)=0),"",CHOOSE(INDEX('Utrekning'!$I$2:$I$41,'Utrekning'!$D$6),"●","▲","■")&IF(INDEX('Utrekning'!$AG$2:$AG$41,'Utrekning'!$D$6)>1," "&INDEX('Utrekning'!$AG$2:$AG$41,'Utrekning'!$D$6),"")&IF($C$6="","",IF(INDEX('Utrekning'!$U$2:$U$41,'Utrekning'!$D$6)=0," ✱",IF(INDEX('Utrekning'!$I$2:$I$41,'Utrekning'!$D$6)>INDEX('Utrekning'!$U$2:$U$41,'Utrekning'!$D$6)," ↑",IF(INDEX('Utrekning'!$I$2:$I$41,'Utrekning'!$D$6)<INDEX('Utrekning'!$U$2:$U$41,'Utrekning'!$D$6)," ↓",""))))) | K13: =IF(OR($B13="",INDEX('Utrekning'!$J$2:$J$41,'Utrekning'!$D$6)=0),"",CHOOSE(INDEX('Utrekning'!$J$2:$J$41,'Utrekning'!$D$6),"●","▲","■")&IF(INDEX('Utrekning'!$AH$2:$AH$41,'Utrekning'!$D$6)>1," "&INDEX('Utrekning'!$AH$2:$AH$41,'Utrekning'!$D$6),"")&IF($C$6="","",IF(INDEX('Utrekning'!$V$2:$V$41,'Utrekning'!$D$6)=0," ✱",IF(INDEX('Utrekning'!$J$2:$J$41,'Utrekning'!$D$6)>INDEX('Utrekning'!$V$2:$V$41,'Utrekning'!$D$6)," ↑",IF(INDEX('Utrekning'!$J$2:$J$41,'Utrekning'!$D$6)<INDEX('Utrekning'!$V$2:$V$41,'Utrekning'!$D$6)," ↓",""))))) | L13: =IF(OR($B13="",INDEX('Utrekning'!$K$2:$K$41,'Utrekning'!$D$6)=0),"",CHOOSE(INDEX('Utrekning'!$K$2:$K$41,'Utrekning'!$D$6),"●","▲","■")&IF(INDEX('Utrekning'!$AI$2:$AI$41,'Utrekning'!$D$6)>1," "&INDEX('Utrekning'!$AI$2:$AI$41,'Utrekning'!$D$6),"")&IF($C$6="","",IF(INDEX('Utrekning'!$W$2:$W$41,'Utrekning'!$D$6)=0," ✱",IF(INDEX('Utrekning'!$K$2:$K$41,'Utrekning'!$D$6)>INDEX('Utrekning'!$W$2:$W$41,'Utrekning'!$D$6)," ↑",IF(INDEX('Utrekning'!$K$2:$K$41,'Utrekning'!$D$6)<INDEX('Utrekning'!$W$2:$W$41,'Utrekning'!$D$6)," ↓",""))))) | M13: =IF(OR($B13="",INDEX('Utrekning'!$L$2:$L$41,'Utrekning'!$D$6)=0),"",CHOOSE(INDEX('Utrekning'!$L$2:$L$41,'Utrekning'!$D$6),"●","▲","■")&IF(INDEX('Utrekning'!$AJ$2:$AJ$41,'Utrekning'!$D$6)>1," "&INDEX('Utrekning'!$AJ$2:$AJ$41,'Utrekning'!$D$6),"")&IF($C$6="","",IF(INDEX('Utrekning'!$X$2:$X$41,'Utrekning'!$D$6)=0," ✱",IF(INDEX('Utrekning'!$L$2:$L$41,'Utrekning'!$D$6)>INDEX('Utrekning'!$X$2:$X$41,'Utrekning'!$D$6)," ↑",IF(INDEX('Utrekning'!$L$2:$L$41,'Utrekning'!$D$6)<INDEX('Utrekning'!$X$2:$X$41,'Utrekning'!$D$6)," ↓",""))))) | N13: =IF(OR($B13="",INDEX('Utrekning'!$M$2:$M$41,'Utrekning'!$D$6)=0),"",CHOOSE(INDEX('Utrekning'!$M$2:$M$41,'Utrekning'!$D$6),"●","▲","■")&IF(INDEX('Utrekning'!$AK$2:$AK$41,'Utrekning'!$D$6)>1," "&INDEX('Utrekning'!$AK$2:$AK$41,'Utrekning'!$D$6),"")&IF($C$6="","",IF(INDEX('Utrekning'!$Y$2:$Y$41,'Utrekning'!$D$6)=0," ✱",IF(INDEX('Utrekning'!$M$2:$M$41,'Utrekning'!$D$6)>INDEX('Utrekning'!$Y$2:$Y$41,'Utrekning'!$D$6)," ↑",IF(INDEX('Utrekning'!$M$2:$M$41,'Utrekning'!$D$6)<INDEX('Utrekning'!$Y$2:$Y$41,'Utrekning'!$D$6)," ↓",""))))) | O13: =IF(OR($B13="",INDEX('Utrekning'!$N$2:$N$41,'Utrekning'!$D$6)=0),"",CHOOSE(INDEX('Utrekning'!$N$2:$N$41,'Utrekning'!$D$6),"●","▲","■")&IF(INDEX('Utrekning'!$AL$2:$AL$41,'Utrekning'!$D$6)>1," "&INDEX('Utrekning'!$AL$2:$AL$41,'Utrekning'!$D$6),"")&IF($C$6="","",IF(INDEX('Utrekning'!$Z$2:$Z$41,'Utrekning'!$D$6)=0," ✱",IF(INDEX('Utrekning'!$N$2:$N$41,'Utrekning'!$D$6)>INDEX('Utrekning'!$Z$2:$Z$41,'Utrekning'!$D$6)," ↑",IF(INDEX('Utrekning'!$N$2:$N$41,'Utrekning'!$D$6)<INDEX('Utrekning'!$Z$2:$Z$41,'Utrekning'!$D$6)," ↓",""))))) | P13: =IF(OR($B13="",INDEX('Utrekning'!$O$2:$O$41,'Utrekning'!$D$6)=0),"",CHOOSE(INDEX('Utrekning'!$O$2:$O$41,'Utrekning'!$D$6),"●","▲","■")&IF(INDEX('Utrekning'!$AM$2:$AM$41,'Utrekning'!$D$6)>1," "&INDEX('Utrekning'!$AM$2:$AM$41,'Utrekning'!$D$6),"")&IF($C$6="","",IF(INDEX('Utrekning'!$AA$2:$AA$41,'Utrekning'!$D$6)=0," ✱",IF(INDEX('Utrekning'!$O$2:$O$41,'Utrekning'!$D$6)>INDEX('Utrekning'!$AA$2:$AA$41,'Utrekning'!$D$6)," ↑",IF(INDEX('Utrekning'!$O$2:$O$41,'Utrekning'!$D$6)<INDEX('Utrekning'!$AA$2:$AA$41,'Utrekning'!$D$6)," ↓",""))))) | Q13: =IF(OR($B13="",INDEX('Utrekning'!$P$2:$P$41,'Utrekning'!$D$6)=0),"",CHOOSE(INDEX('Utrekning'!$P$2:$P$41,'Utrekning'!$D$6),"●","▲","■")&IF(INDEX('Utrekning'!$AN$2:$AN$41,'Utrekning'!$D$6)>1," "&INDEX('Utrekning'!$AN$2:$AN$41,'Utrekning'!$D$6),"")&IF($C$6="","",IF(INDEX('Utrekning'!$AB$2:$AB$41,'Utrekning'!$D$6)=0," ✱",IF(INDEX('Utrekning'!$P$2:$P$41,'Utrekning'!$D$6)>INDEX('Utrekning'!$AB$2:$AB$41,'Utrekning'!$D$6)," ↑",IF(INDEX('Utrekning'!$P$2:$P$41,'Utrekning'!$D$6)<INDEX('Utrekning'!$AB$2:$AB$41,'Utrekning'!$D$6)," ↓","")))))
B14: =IFERROR(INDEX('Utrekning'!$B$2:$B$41,'Utrekning'!$D$7),"") | C14: =IF($B14="","",COUNTIF(INDEX('Utrekning'!$E$2:$P$41,'Utrekning'!$D$7,0),3)) | D14: =IF($B14="","",COUNTIF(INDEX('Utrekning'!$E$2:$P$41,'Utrekning'!$D$7,0),2)) | E14: =IF($B14="","",COUNTIFS('Tiltak'!$B$2:$B$251,$C$5,'Tiltak'!$C$2:$C$251,$B14,'Tiltak'!$E$2:$E$251,"<>",'Tiltak'!$H$2:$H$251,"<>Avslutta",'Tiltak'!$H$2:$H$251,"<>Avsluttet")) | F14: =IF(OR($B14="",INDEX('Utrekning'!$E$2:$E$41,'Utrekning'!$D$7)=0),"",CHOOSE(INDEX('Utrekning'!$E$2:$E$41,'Utrekning'!$D$7),"●","▲","■")&IF(INDEX('Utrekning'!$AC$2:$AC$41,'Utrekning'!$D$7)>1," "&INDEX('Utrekning'!$AC$2:$AC$41,'Utrekning'!$D$7),"")&IF($C$6="","",IF(INDEX('Utrekning'!$Q$2:$Q$41,'Utrekning'!$D$7)=0," ✱",IF(INDEX('Utrekning'!$E$2:$E$41,'Utrekning'!$D$7)>INDEX('Utrekning'!$Q$2:$Q$41,'Utrekning'!$D$7)," ↑",IF(INDEX('Utrekning'!$E$2:$E$41,'Utrekning'!$D$7)<INDEX('Utrekning'!$Q$2:$Q$41,'Utrekning'!$D$7)," ↓",""))))) | G14: =IF(OR($B14="",INDEX('Utrekning'!$F$2:$F$41,'Utrekning'!$D$7)=0),"",CHOOSE(INDEX('Utrekning'!$F$2:$F$41,'Utrekning'!$D$7),"●","▲","■")&IF(INDEX('Utrekning'!$AD$2:$AD$41,'Utrekning'!$D$7)>1," "&INDEX('Utrekning'!$AD$2:$AD$41,'Utrekning'!$D$7),"")&IF($C$6="","",IF(INDEX('Utrekning'!$R$2:$R$41,'Utrekning'!$D$7)=0," ✱",IF(INDEX('Utrekning'!$F$2:$F$41,'Utrekning'!$D$7)>INDEX('Utrekning'!$R$2:$R$41,'Utrekning'!$D$7)," ↑",IF(INDEX('Utrekning'!$F$2:$F$41,'Utrekning'!$D$7)<INDEX('Utrekning'!$R$2:$R$41,'Utrekning'!$D$7)," ↓",""))))) | H14: =IF(OR($B14="",INDEX('Utrekning'!$G$2:$G$41,'Utrekning'!$D$7)=0),"",CHOOSE(INDEX('Utrekning'!$G$2:$G$41,'Utrekning'!$D$7),"●","▲","■")&IF(INDEX('Utrekning'!$AE$2:$AE$41,'Utrekning'!$D$7)>1," "&INDEX('Utrekning'!$AE$2:$AE$41,'Utrekning'!$D$7),"")&IF($C$6="","",IF(INDEX('Utrekning'!$S$2:$S$41,'Utrekning'!$D$7)=0," ✱",IF(INDEX('Utrekning'!$G$2:$G$41,'Utrekning'!$D$7)>INDEX('Utrekning'!$S$2:$S$41,'Utrekning'!$D$7)," ↑",IF(INDEX('Utrekning'!$G$2:$G$41,'Utrekning'!$D$7)<INDEX('Utrekning'!$S$2:$S$41,'Utrekning'!$D$7)," ↓",""))))) | I14: =IF(OR($B14="",INDEX('Utrekning'!$H$2:$H$41,'Utrekning'!$D$7)=0),"",CHOOSE(INDEX('Utrekning'!$H$2:$H$41,'Utrekning'!$D$7),"●","▲","■")&IF(INDEX('Utrekning'!$AF$2:$AF$41,'Utrekning'!$D$7)>1," "&INDEX('Utrekning'!$AF$2:$AF$41,'Utrekning'!$D$7),"")&IF($C$6="","",IF(INDEX('Utrekning'!$T$2:$T$41,'Utrekning'!$D$7)=0," ✱",IF(INDEX('Utrekning'!$H$2:$H$41,'Utrekning'!$D$7)>INDEX('Utrekning'!$T$2:$T$41,'Utrekning'!$D$7)," ↑",IF(INDEX('Utrekning'!$H$2:$H$41,'Utrekning'!$D$7)<INDEX('Utrekning'!$T$2:$T$41,'Utrekning'!$D$7)," ↓",""))))) | J14: =IF(OR($B14="",INDEX('Utrekning'!$I$2:$I$41,'Utrekning'!$D$7)=0),"",CHOOSE(INDEX('Utrekning'!$I$2:$I$41,'Utrekning'!$D$7),"●","▲","■")&IF(INDEX('Utrekning'!$AG$2:$AG$41,'Utrekning'!$D$7)>1," "&INDEX('Utrekning'!$AG$2:$AG$41,'Utrekning'!$D$7),"")&IF($C$6="","",IF(INDEX('Utrekning'!$U$2:$U$41,'Utrekning'!$D$7)=0," ✱",IF(INDEX('Utrekning'!$I$2:$I$41,'Utrekning'!$D$7)>INDEX('Utrekning'!$U$2:$U$41,'Utrekning'!$D$7)," ↑",IF(INDEX('Utrekning'!$I$2:$I$41,'Utrekning'!$D$7)<INDEX('Utrekning'!$U$2:$U$41,'Utrekning'!$D$7)," ↓",""))))) | K14: =IF(OR($B14="",INDEX('Utrekning'!$J$2:$J$41,'Utrekning'!$D$7)=0),"",CHOOSE(INDEX('Utrekning'!$J$2:$J$41,'Utrekning'!$D$7),"●","▲","■")&IF(INDEX('Utrekning'!$AH$2:$AH$41,'Utrekning'!$D$7)>1," "&INDEX('Utrekning'!$AH$2:$AH$41,'Utrekning'!$D$7),"")&IF($C$6="","",IF(INDEX('Utrekning'!$V$2:$V$41,'Utrekning'!$D$7)=0," ✱",IF(INDEX('Utrekning'!$J$2:$J$41,'Utrekning'!$D$7)>INDEX('Utrekning'!$V$2:$V$41,'Utrekning'!$D$7)," ↑",IF(INDEX('Utrekning'!$J$2:$J$41,'Utrekning'!$D$7)<INDEX('Utrekning'!$V$2:$V$41,'Utrekning'!$D$7)," ↓",""))))) | L14: =IF(OR($B14="",INDEX('Utrekning'!$K$2:$K$41,'Utrekning'!$D$7)=0),"",CHOOSE(INDEX('Utrekning'!$K$2:$K$41,'Utrekning'!$D$7),"●","▲","■")&IF(INDEX('Utrekning'!$AI$2:$AI$41,'Utrekning'!$D$7)>1," "&INDEX('Utrekning'!$AI$2:$AI$41,'Utrekning'!$D$7),"")&IF($C$6="","",IF(INDEX('Utrekning'!$W$2:$W$41,'Utrekning'!$D$7)=0," ✱",IF(INDEX('Utrekning'!$K$2:$K$41,'Utrekning'!$D$7)>INDEX('Utrekning'!$W$2:$W$41,'Utrekning'!$D$7)," ↑",IF(INDEX('Utrekning'!$K$2:$K$41,'Utrekning'!$D$7)<INDEX('Utrekning'!$W$2:$W$41,'Utrekning'!$D$7)," ↓",""))))) | M14: =IF(OR($B14="",INDEX('Utrekning'!$L$2:$L$41,'Utrekning'!$D$7)=0),"",CHOOSE(INDEX('Utrekning'!$L$2:$L$41,'Utrekning'!$D$7),"●","▲","■")&IF(INDEX('Utrekning'!$AJ$2:$AJ$41,'Utrekning'!$D$7)>1," "&INDEX('Utrekning'!$AJ$2:$AJ$41,'Utrekning'!$D$7),"")&IF($C$6="","",IF(INDEX('Utrekning'!$X$2:$X$41,'Utrekning'!$D$7)=0," ✱",IF(INDEX('Utrekning'!$L$2:$L$41,'Utrekning'!$D$7)>INDEX('Utrekning'!$X$2:$X$41,'Utrekning'!$D$7)," ↑",IF(INDEX('Utrekning'!$L$2:$L$41,'Utrekning'!$D$7)<INDEX('Utrekning'!$X$2:$X$41,'Utrekning'!$D$7)," ↓",""))))) | N14: =IF(OR($B14="",INDEX('Utrekning'!$M$2:$M$41,'Utrekning'!$D$7)=0),"",CHOOSE(INDEX('Utrekning'!$M$2:$M$41,'Utrekning'!$D$7),"●","▲","■")&IF(INDEX('Utrekning'!$AK$2:$AK$41,'Utrekning'!$D$7)>1," "&INDEX('Utrekning'!$AK$2:$AK$41,'Utrekning'!$D$7),"")&IF($C$6="","",IF(INDEX('Utrekning'!$Y$2:$Y$41,'Utrekning'!$D$7)=0," ✱",IF(INDEX('Utrekning'!$M$2:$M$41,'Utrekning'!$D$7)>INDEX('Utrekning'!$Y$2:$Y$41,'Utrekning'!$D$7)," ↑",IF(INDEX('Utrekning'!$M$2:$M$41,'Utrekning'!$D$7)<INDEX('Utrekning'!$Y$2:$Y$41,'Utrekning'!$D$7)," ↓",""))))) | O14: =IF(OR($B14="",INDEX('Utrekning'!$N$2:$N$41,'Utrekning'!$D$7)=0),"",CHOOSE(INDEX('Utrekning'!$N$2:$N$41,'Utrekning'!$D$7),"●","▲","■")&IF(INDEX('Utrekning'!$AL$2:$AL$41,'Utrekning'!$D$7)>1," "&INDEX('Utrekning'!$AL$2:$AL$41,'Utrekning'!$D$7),"")&IF($C$6="","",IF(INDEX('Utrekning'!$Z$2:$Z$41,'Utrekning'!$D$7)=0," ✱",IF(INDEX('Utrekning'!$N$2:$N$41,'Utrekning'!$D$7)>INDEX('Utrekning'!$Z$2:$Z$41,'Utrekning'!$D$7)," ↑",IF(INDEX('Utrekning'!$N$2:$N$41,'Utrekning'!$D$7)<INDEX('Utrekning'!$Z$2:$Z$41,'Utrekning'!$D$7)," ↓",""))))) | P14: =IF(OR($B14="",INDEX('Utrekning'!$O$2:$O$41,'Utrekning'!$D$7)=0),"",CHOOSE(INDEX('Utrekning'!$O$2:$O$41,'Utrekning'!$D$7),"●","▲","■")&IF(INDEX('Utrekning'!$AM$2:$AM$41,'Utrekning'!$D$7)>1," "&INDEX('Utrekning'!$AM$2:$AM$41,'Utrekning'!$D$7),"")&IF($C$6="","",IF(INDEX('Utrekning'!$AA$2:$AA$41,'Utrekning'!$D$7)=0," ✱",IF(INDEX('Utrekning'!$O$2:$O$41,'Utrekning'!$D$7)>INDEX('Utrekning'!$AA$2:$AA$41,'Utrekning'!$D$7)," ↑",IF(INDEX('Utrekning'!$O$2:$O$41,'Utrekning'!$D$7)<INDEX('Utrekning'!$AA$2:$AA$41,'Utrekning'!$D$7)," ↓",""))))) | Q14: =IF(OR($B14="",INDEX('Utrekning'!$P$2:$P$41,'Utrekning'!$D$7)=0),"",CHOOSE(INDEX('Utrekning'!$P$2:$P$41,'Utrekning'!$D$7),"●","▲","■")&IF(INDEX('Utrekning'!$AN$2:$AN$41,'Utrekning'!$D$7)>1," "&INDEX('Utrekning'!$AN$2:$AN$41,'Utrekning'!$D$7),"")&IF($C$6="","",IF(INDEX('Utrekning'!$AB$2:$AB$41,'Utrekning'!$D$7)=0," ✱",IF(INDEX('Utrekning'!$P$2:$P$41,'Utrekning'!$D$7)>INDEX('Utrekning'!$AB$2:$AB$41,'Utrekning'!$D$7)," ↑",IF(INDEX('Utrekning'!$P$2:$P$41,'Utrekning'!$D$7)<INDEX('Utrekning'!$AB$2:$AB$41,'Utrekning'!$D$7)," ↓","")))))
